Workbook

Sheet portfolio_7_50
A1: Loan Product Variables | B1: loan program | C1: loan_term | D1: Avg Loan Size $'s | E1: coupon | F1: cdr_promo | G1: constant_cpr | H1: servicing_cost | I1: late_percent | J1: recovery_percent | K1: promo_term | L1: Promo Period Prepayment | M1: modeled_purchase_price | N1: SFC Loan Margin | O1: SFC Purchase Price | P1: Merchant Discount | Q1: cdr | R1: yield | S1: weight | T1: weight(old) | U1: weight(worst case) | V1: Purchase Price(Worst Case) | W1: tagging | X1: cpr | Y1: platform | Z1: type | AA1: proposed_cdr_promo | AB1: proposed_cdr | AC1: proposed_cpr | AD1: proposed_promo_cpr_percent | AE1: irr_support
A2: WP12 | B2: 12 Mth WPDI | C2: 58 | D2: 10000 | E2: 2136 | F2: 0.0247 | G2: 0.2803 | H2: 0.02 | I2: 2e-05 | J2: 0.35 | K2: 12 | L2: 0.75340353 | M2: =O2+N2 -> 0.955 | N2: 0.0125 | O2: 0.9425 | P2: 0.0575 | Q2: 0.0391 | R2: 0.12920518 | S2: 0.02535 | T2: 0.0046046391 | U2: 0 | V2: =U2*(500000000/12) -> 0 | W2: PRIME | X2: 0.0857487051848048;0.0610754496958203;0.0513105837504979;0.0531944018026846;0.0498039384711616;0.0484632728430639;0.0530638880524382;0.0460181756381459;0.0535151570899108;0.0609918936727764;0.0897706022746428;0.100447462086909 | Y2: prime | Z2: wpdi | AA2: 0.03211 | AB2: 0.04696692 | AC2: 0.28 | AD2: 1 | AE2: 0.0125
A3: WP12-2395 | B3: 12 Mth WPDI - 2395 | C3: 58 | D3: 10000 | E3: 2022 | F3: 0.0312 | G3: 0.236 | H3: 0.02 | I3: 2e-05 | J3: 0.35 | K3: 12 | L3: 0.75340353 | M3: =O3+N3 -> 0.9675 | N3: 0.0125 | O3: 0.955 | P3: 0.045 | Q3: 0.0312 | R3: 0.10617216 | S3: 0.0036 | T3: 0.0025506884 | U3: 0 | V3: =U3*(500000000/12) -> 0 | W3: PRIME | X3: 0.0857487051848048;0.0610754496958203;0.0513105837504979;0.0531944018026846;0.0498039384711616;0.0484632728430639;0.0530638880524382;0.0460181756381459;0.0535151570899108;0.0609918936727764;0.0897706022746428;0.100447462086909 | Y3: prime | Z3: wpdi | AA3: 0.04056 | AB3: 0.0468468 | AC3: 0.2714 | AD3: 1 | AE3: 0.0125
A4: WP18 | B4: 18 Mth WPDI | C4: 59 | D4: 10000 | E4: 2136 | F4: 0.0186 | G4: 0.2705 | H4: 0.02 | I4: 2e-05 | J4: 0.35 | K4: 18 | L4: 0.78556326 | M4: =O4+N4 -> 0.9595 | N4: 0.0125 | O4: 0.947 | P4: 0.053 | Q4: 0.0531 | R4: 0.096218476 | S4: 0.01295 | T4: 0.018253998 | U4: 0.05 | V4: =U4*(500000000/12) -> 2083333.3 | W4: PRIME | X4: 0.0628324181433995;0.0408385410486935;0.0369529552615553;0.0342505855761147;0.0360444673455377;0.0342760224870836;0.034925225567199;0.0325781332673581;0.033301047422053;0.0336283273168834;0.036171644516601;0.0363542883332323;0.0358565574961247;0.0356553513213916;0.039832222527633;0.0498596224428832;0.0778039535101948;0.094401901081233 | Y4: prime | Z4: wpdi | AA4: 0.015 | AB4: 0.05 | AC4: 0.25 | AD4: 1 | AE4: 0.0125
A5: WP18-2395 | B5: 18 Mth WPDI - 2395 | C5: 58 | D5: 10000 | E5: 2022 | F5: 0.0158 | G5: 0.2591 | H5: 0.02 | I5: 2e-05 | J5: 0.35 | K5: 18 | L5: 0.78556326 | M5: =O5+N5 -> 0.9425 | N5: 0.0125 | O5: 0.93 | P5: 0.07 | Q5: 0.0438 | R5: 0.11215601 | S5: 0.00035 | T5: 0.0017767424 | U5: 0 | V5: =U5*(500000000/12) -> 0 | W5: PRIME | X5: 0.0628324181433995;0.0408385410486935;0.0369529552615553;0.0342505855761147;0.0360444673455377;0.0342760224870836;0.034925225567199;0.0325781332673581;0.033301047422053;0.0336283273168834;0.036171644516601;0.0363542883332323;0.0358565574961247;0.0356553513213916;0.039832222527633;0.0498596224428832;0.0778039535101948;0.094401901081233 | Y5: prime | Z5: wpdi | AA5: 0.02054 | AB5: 0.055 | AC5: 0.297965 | AD5: 1 | AE5: 0.0125
A6: WP24 | B6: 24 Mth WPDI | C6: 59 | D6: 10000 | E6: 2136 | F6: 0.0291 | G6: 0.1948 | H6: 0.02 | I6: 2e-05 | J6: 0.35 | K6: 24 | L6: 0.81138877 | M6: =O6+N6 -> 0.9292 | N6: 0.0125 | O6: 0.9167 | P6: 0.0833 | Q6: 0.0123 | R6: 0.1032113 | S6: 0.0013 | T6: 0.0036548922 | U6: 0 | V6: =U6*(500000000/12) -> 0 | W6: PRIME | X6: 0.0538802514747746;0.0450107112074825;0.0290435059631223;0.0269110688933608;0.0329133419615629;0.03778226424726;0.0232883570793076;0.0303450750062364;0.0278511944142547;0.0204041596515225;0.0287588205249249;0.024276493719799;0.0203752870880823;0.0263855276501278;0.0264984370739482;0.0311667302716944;0.0266788484511471;0.0229199465675228;0.0239449730692468;0.0281456717931416;0.0348539461672305;0.049331336098592;0.0713419744929187;0.0692808423423899 | Y6: prime | Z6: wpdi | AA6: 0.02883728 | AB6: 0.0225 | AC6: 0.2 | AD6: 1 | AE6: 0.0125
A7: WP24-2395 | B7: 24 Mth WPDI - 2395 | C7: 58 | D7: 10000 | E7: 1931 | F7: 0.0199 | G7: 0.1607 | H7: 0.02 | I7: 2e-05 | J7: 0.35 | K7: 24 | L7: 0.81138877 | M7: =O7+N7 -> 0.9225 | N7: 0.0125 | O7: 0.91 | P7: 0.09 | Q7: 0.0226 | R7: 0.10872926 | S7: 0.0004 | T7: 0.0017522715 | U7: 0 | V7: =U7*(500000000/12) -> 0 | W7: PRIME | X7: 0.0538802514747746;0.0450107112074825;0.0290435059631223;0.0269110688933608;0.0329133419615629;0.03778226424726;0.0232883570793076;0.0303450750062364;0.0278511944142547;0.0204041596515225;0.0287588205249249;0.024276493719799;0.0203752870880823;0.0263855276501278;0.0264984370739482;0.0311667302716944;0.0266788484511471;0.0229199465675228;0.0239449730692468;0.0281456717931416;0.0348539461672305;0.049331336098592;0.0713419744929187;0.0692808423423899 | Y7: prime | Z7: wpdi | AA7: 0.02587 | AB7: 0.0339339 | AC7: 0.184805 | AD7: 1 | AE7: 0.0125
A8: WP6 | B8: 6 Mth WPDI | C8: 57 | D8: 10000 | E8: 2136 | F8: 0.0601 | G8: 0.2243 | H8: 0.02 | I8: 2e-05 | J8: 0.35 | K8: 6 | L8: 0.60178709 | M8: =O8+N8 -> 0.9779 | N8: 0.0125 | O8: 0.9654 | P8: 0.0346 | Q8: 0.0213 | R8: 0.14802476 | S8: 0.0033 | T8: 0.0071057311 | U8: 0 | V8: =U8*(500000000/12) -> 0 | W8: PRIME | X8: 0.127193115890202;0.0983579230509763;0.0684690070488666;0.0780269469612146;0.10649516707994;0.123244925532516 | Y8: prime | Z8: wpdi | AA8: 0.0726 | AB8: 0.065 | AC8: 0.22 | AD8: 1 | AE8: 0.0125
A9: NINP10 | B9: NINP - 10 Mo | C9: 85 | D9: 10000 | E9: 2145 | F9: 0.0155 | G9: 0.4075 | H9: 0.02 | I9: 2e-05 | J9: 0.35 | K9: 10 | L9: 0.7703 | M9: =O9+N9 -> 0.9579 | N9: 0.0125 | O9: 0.9454 | P9: 0.0546 | Q9: 0.049 | R9: 0.077643508 | S9: 0.15835 | T9: 0.16519106 | U9: 0 | V9: =U9*(500000000/12) -> 0 | W9: PRIME | X9: 0.0709;0.0504;0.0504;0.0504;0.0504;0.0504;0.0504;0.0709;0.1132;0.1649 | Y9: prime | Z9: ninp | AA9: 0.0266 | AB9: 0.049 | AC9: 0.4 | AD9: 1 | AE9: 0.0125
A10: NINP14 | B10: NINP - 14 Mo | C10: 92 | D10: 10000 | E10: 2145 | F10: 0.0133 | G10: 0.336 | H10: 0.02 | I10: 2e-05 | J10: 0.35 | K10: 14 | L10: 0.7754 | M10: =O10+N10 -> 0.9383 | N10: 0.0125 | O10: 0.9258 | P10: 0.0742 | Q10: 0.0647 | R10: 0.075389505 | S10: 0.0353 | T10: 0.042781033 | U10: 0.08 | V10: =U10*(500000000/12) -> 3333333.3 | W10: PRIME | X10: 0.0616;0.0411;0.0411;0.0411;0.0411;0.0411;0.0411;0.0411;0.0411;0.0411;0.0411;0.0539;0.0924;0.1565 | Y10: prime | Z10: ninp | AA10: 0.0277 | AB10: 0.0647 | AC10: 0.35 | AD10: 1 | AE10: 0.0125
A11: NINP20 | B11: NINP - 20 Mo | C11: 99 | D11: 10000 | E11: 2145 | F11: 0.0114 | G11: 0.3365 | H11: 0.02 | I11: 2e-05 | J11: 0.35 | K11: 20 | L11: 0.7803 | M11: =O11+N11 -> 0.8973 | N11: 0.0125 | O11: 0.8848 | P11: 0.1152 | Q11: 0.0726 | R11: 0.082151175 | S11: 0.0066 | T11: 0.011901401 | U11: 0 | V11: =U11*(500000000/12) -> 0 | W11: PRIME | X11: 0.046;0.0307;0.0307;0.0307;0.0307;0.0307;0.0307;0.0307;0.0307;0.0307;0.0307;0.0307;0.0307;0.0307;0.0307;0.0307;0.0307;0.0471;0.0911;0.1049 | Y11: prime | Z11: ninp | AA11: 0.0257 | AB11: 0.0726 | AC11: 0.3365 | AD11: 1 | AE11: 0.0125
A12: NINP24 | B12: NINP - 24 Mo | C12: 96 | D12: 10000 | E12: 2399 | F12: 0.0052 | G12: 0.5 | H12: 0.02 | I12: 2e-05 | J12: 0.35 | K12: 24 | L12: 0.8836 | M12: =O12+N12 -> 0.8989 | N12: 0.0125 | O12: 0.8864 | P12: 0.1136 | Q12: 0.0052 | R12: 0.071474241 | S12: 0.0135 | T12: 0.014816137 | U12: 0 | V12: =U12*(500000000/12) -> 0 | W12: PRIME | X12: 0.0302682303390938;0.0356001359822339;0.0264899498130113;0.0278713659278495;0.0237586612170386;0.0257922068481641;0.0212229312672512;0.0296325482161332;0.0295657455342041;0.0308287508657281;0.0381673706394066;0.0308324037932695;0.0308955187188472;0.028723292961373;0.032676297334632;0.0210930382447866;0.0277371162310062;0.0370975473999753;0.035807390962314;0.035803371307891;0.0363913891800091;0.0638536190282034;0.0865123925721557;0.0969787256154225 | Y12: prime | Z12: ninp | AA12: 0.00676 | AB12: 0.010395 | AC12: 0.5 | AD12: 1 | AE12: 0.0125
A13: 1090 - 120 | B13: Unsec Std - 1090 - 120 | C13: 120 | D13: 10000 | E13: 1090 | F13: 0 | G13: 0.16959519 | H13: 0.02 | I13: 2e-05 | J13: 0.35 | K13: 0 | M13: =O13+N13 -> 1.0072 | N13: 0.0125 | O13: 0.9947 | P13: 0.0053 | Q13: 0.0166 | R13: 0.074356817 | S13: 0.00845 | T13: 0.017188328 | U13: 0 | V13: =U13*(500000000/12) -> 0 | W13: PRIME | X13: 0 | Y13: prime | Z13: standard | AA13: 0 | AB13: 0.0203675 | AC13: 0.18 | AD13: 1 | AE13: 0.0125
A14: NINP4337 | B14: Unsec Std - 1090 - 123 | C14: 123 | D14: 10000 | E14: 1090 | F14: 0.0166 | G14: 0.1696 | H14: 0.02 | I14: 2e-05 | J14: 0.35 | K14: 3 | L14: 0.13 | M14: =O14+N14 -> 0.9612 | N14: 0.0125 | O14: 0.9487 | P14: 0.0513 | Q14: 0.0166 | R14: 0.082257609 | S14: 0.0015 | T14: 0.0021465649 | U14: 0 | V14: =U14*(500000000/12) -> 0 | W14: PRIME | X14: 0.0363405847853139;0.0425899377937978;0.0510694774208883 | Y14: prime | Z14: hybrid | AA14: 0.025314139 | AB14: 0.035 | AC14: 0.2 | AD14: 1 | AE14: 0.0125
A15: 1090 - 180 | B15: Unsec Std - 1090 - 180 | C15: 180 | D15: 10000 | E15: 1090 | F15: 0 | G15: 0.15068525 | H15: 0.02 | I15: 2e-05 | J15: 0.35 | K15: 0 | M15: =O15+N15 -> 0.9858 | N15: 0.0125 | O15: 0.9733 | P15: 0.0267 | Q15: 0.0278 | R15: 0.07332254 | S15: 0.03245 | T15: 0.0078515045 | U15: 0 | V15: =U15*(500000000/12) -> 0 | W15: PRIME | X15: 0 | Y15: prime | Z15: standard | AA15: 0 | AB15: 0.03 | AC15: 0.15 | AD15: 1 | AE15: 0.0125
A16: 1190 - 120 | B16: Unsec Std - 1190 - 120 | C16: 120 | D16: 10000 | E16: 1190 | F16: 0 | G16: 0.14100859 | H16: 0.02 | I16: 2e-05 | J16: 0.35 | K16: 0 | M16: =O16+N16 -> 1.0016 | N16: 0.0125 | O16: 0.9891 | P16: 0.0109 | Q16: 0.0298 | R16: 0.07677732 | S16: 0.00095 | T16: 0.00042416242 | U16: 0 | V16: =U16*(500000000/12) -> 0 | W16: PRIME | X16: 0 | Y16: prime | Z16: standard | AA16: 0 | AB16: 0.045276 | AC16: 0.15 | AD16: 1 | AE16: 0.0125
A17: NINP4342 | B17: Unsec Std - 1190 - 123 | C17: 123 | D17: 10000 | E17: 1190 | F17: 0.0298 | G17: 0.141 | H17: 0.02 | I17: 2e-05 | J17: 0.35 | K17: 3 | L17: 0.13 | M17: =O17+N17 -> 0.9599 | N17: 0.0125 | O17: 0.9474 | P17: 0.0526 | Q17: 0.0298 | R17: 0.081911142 | S17: 0.0004 | T17: 0.00058221026 | U17: 0 | V17: =U17*(500000000/12) -> 0 | W17: PRIME | X17: 0.0363405847853139;0.0425899377937978;0.0510694774208883 | Y17: prime | Z17: hybrid | AA17: 0.039 | AB17: 0.0462 | AC17: 0.2 | AD17: 1 | AE17: 0.0125
A18: NINP1190-126 | B18: Unsec Std - 1190 - 126 | C18: 126 | D18: 10000 | E18: 1190 | F18: 0.0186 | G18: 0.316 | H18: 0.02 | I18: 2e-05 | J18: 0.35 | K18: 6 | L18: 0.25257766 | M18: =O18+N18 -> 0.9625 | N18: 0.0125 | O18: 0.95 | P18: 0.05 | Q18: 0.0186 | R18: 0.076594128 | S18: 0.0003 | T18: 0.00056007877 | U18: 0 | V18: =U18*(500000000/12) -> 0 | W18: PRIME | X18: 0.0304101228333604;0.0285764276898905;0.0302839020107548;0.0381893037751229;0.0532504811001973;0.0718674265305649 | Y18: prime | Z18: hybrid | AA18: 0.024141871 | AB18: 0.027883861 | AC18: 0.3634 | AD18: 1 | AE18: 0.0125
A19: 1190 - 144 | B19: Unsec Std - 1190 - 144 | C19: 144 | D19: 10000 | E19: 1190 | F19: 0 | G19: 0.097 | H19: 0.02 | I19: 2e-05 | J19: 0.35 | K19: 0 | M19: =O19+N19 -> 0.9304 | N19: 0.0125 | O19: 0.9179 | P19: 0.0821 | Q19: 0.0281 | R19: 0.099398969 | S19: 0.00015 | T19: 0.00061251046 | U19: 0 | V19: =U19*(500000000/12) -> 0 | W19: PRIME | X19: 0 | Y19: prime | Z19: standard | AA19: 0 | AB19: 0.05 | AC19: 0.15 | AD19: 1 | AE19: 0.0125
A20: 1190 - 180 | B20: Unsec Std - 1190 - 180 | C20: 180 | D20: 10000 | E20: 1190 | F20: 0 | G20: 0.1176102 | H20: 0.02 | I20: 2e-05 | J20: 0.35 | K20: 0 | M20: =O20+N20 -> 0.9806 | N20: 0.0125 | O20: 0.9681 | P20: 0.0319 | Q20: 0.0417 | R20: 0.074194454 | S20: 0.00185 | T20: 0.00088010681 | U20: 0.07 | V20: =U20*(500000000/12) -> 2916666.7 | W20: PRIME | X20: 0 | Y20: prime | Z20: standard | AA20: 0 | AB20: 0.0425 | AC20: 0.13851438 | AD20: 1 | AE20: 0.0125
A21: 1190 - 60 | B21: Unsec Std - 1190 - 60 | C21: 60 | D21: 10000 | E21: 1190 | F21: 0 | G21: 0.143 | H21: 0.02 | I21: 2e-05 | J21: 0.35 | K21: 0 | M21: =O21+N21 -> 0.9609 | N21: 0.0125 | O21: 0.9484 | P21: 0.0516 | Q21: 0.019 | R21: 0.10659977 | S21: 0.0001 | T21: 0.00095317399 | U21: 0 | V21: =U21*(500000000/12) -> 0 | W21: PRIME | X21: 0 | Y21: prime | Z21: standard | AA21: 0 | AB21: 0.0325 | AC21: 0.15 | AD21: 1 | AE21: 0.0125
A22: 1195-180 | B22: Unsec Std - 1195 - 180 | C22: 180 | D22: 10000 | E22: 1195 | F22: 0 | G22: 0.2 | H22: 0.02 | I22: 2e-05 | J22: 0.35 | K22: 0 | M22: =O22+N22 -> 1.0125 | N22: 0.0125 | O22: 1 | P22: 0 | Q22: 0.03096595 | R22: 0.072519507 | S22: 0.00295 | T22: 0.00068061467 | U22: 0 | V22: =U22*(500000000/12) -> 0 | W22: PRIME | X22: 0 | Y22: prime | Z22: standard | AA22: 0 | AB22: 0.049153733 | AC22: 0.23 | AD22: 1 | AE22: 0.0125
A23: 1290 - 120 | B23: Unsec Std - 1290 - 120 | C23: 120 | D23: 10000 | E23: 1290 | F23: 0 | G23: 0.13575087 | H23: 0.02 | I23: 2e-05 | J23: 0.35 | K23: 0 | M23: =O23+N23 -> 1.0098 | N23: 0.0125 | O23: 0.9973 | P23: 0.0027 | Q23: 0.0333 | R23: 0.081152152 | S23: 0.0085 | T23: 0.0038510224 | U23: 0.03 | V23: =U23*(500000000/12) -> 1250000 | W23: PRIME | X23: 0 | Y23: prime | Z23: standard | AA23: 0 | AB23: 0.046548 | AC23: 0.15 | AD23: 1 | AE23: 0.0125
A24: NINP4348 | B24: Unsec Std - 1290 - 123 | C24: 123 | D24: 10000 | E24: 1290 | F24: 0.0333 | G24: 0.1358 | H24: 0.02 | I24: 2e-05 | J24: 0.35 | K24: 3 | L24: 0.13 | M24: =O24+N24 -> 0.9562 | N24: 0.0125 | O24: 0.9437 | P24: 0.0563 | Q24: 0.0333 | R24: 0.089698325 | S24: 0.0036 | T24: 0.0041089336 | U24: 0 | V24: =U24*(500000000/12) -> 0 | W24: PRIME | X24: 0.0363405847853139;0.0425899377937978;0.0510694774208883 | Y24: prime | Z24: hybrid | AA24: 0.0449 | AB24: 0.0575 | AC24: 0.15 | AD24: 1 | AE24: 0.0125
A25: 1389 - 120 | B25: Unsec Std - 1389 - 120 | C25: 120 | D25: 10000 | E25: 1389 | F25: 0 | G25: 0.13376435 | H25: 0.02 | I25: 2e-05 | J25: 0.35 | K25: 0 | M25: =O25+N25 -> 1.0053 | N25: 0.0125 | O25: 0.9928 | P25: 0.0072 | Q25: 0.0346 | R25: 0.09139627 | S25: 0.0019 | T25: 0.0010720097 | U25: 0 | V25: =U25*(500000000/12) -> 0 | W25: PRIME | X25: 0 | Y25: prime | Z25: standard | AA25: 0 | AB25: 0.0537075 | AC25: 0.17 | AD25: 1 | AE25: 0.0125
A26: NINP4355 | B26: Unsec Std - 1390 - 123 | C26: 123 | D26: 10000 | E26: 1390 | F26: 0.0346 | G26: 0.1338 | H26: 0.02 | I26: 2e-05 | J26: 0.35 | K26: 3 | L26: 0.13 | M26: =O26+N26 -> 0.9557 | N26: 0.0125 | O26: 0.9432 | P26: 0.0568 | Q26: 0.0346 | R26: 0.097856834 | S26: 0.0005 | T26: 0.00028495485 | U26: 0 | V26: =U26*(500000000/12) -> 0 | W26: PRIME | X26: 0.0363405847853139;0.0425899377937978;0.0510694774208883 | Y26: prime | Z26: hybrid | AA26: 0.057635613 | AB26: 0.069926 | AC26: 0.2 | AD26: 1 | AE26: 0.0125
A27: 1390 - 144 | B27: Unsec Std - 1390 - 144 | C27: 144 | D27: 10000 | E27: 1390 | F27: 0 | G27: 0.0701 | H27: 0.02 | I27: 2e-05 | J27: 0.35 | K27: 0 | M27: =O27+N27 -> 0.9475 | N27: 0.0125 | O27: 0.935 | P27: 0.065 | Q27: 0.0356 | R27: 0.10744451 | S27: 0 | T27: 0.00032009929 | U27: 0 | V27: =U27*(500000000/12) -> 0 | W27: PRIME | X27: 0 | Y27: prime | Z27: standard | AA27: 0 | AB27: 0.060776831 | AC27: 0.12 | AD27: 1 | AE27: 0.0125
A28: 795-180 | B28: Unsec Std - 795 - 180 | C28: 180 | D28: 10000 | E28: 795 | F28: 0 | G28: 0.2 | H28: 0.02 | I28: 2e-05 | J28: 0.35 | K28: 0 | M28: =O28+N28 -> 0.9075 | N28: 0.0125 | O28: 0.895 | P28: 0.105 | Q28: 0.03096595 | R28: 0.071880448 | S28: 0.01425 | T28: 0.007120866 | U28: 0 | V28: =U28*(500000000/12) -> 0 | W28: PRIME | X28: 0 | Y28: prime | Z28: standard | AA28: 0 | AB28: 0.04 | AC28: 0.23 | AD28: 1 | AE28: 0.0125
A29: 895-180 | B29: Unsec Std - 895 - 180 | C29: 180 | D29: 10000 | E29: 895 | F29: 0 | G29: 0.2 | H29: 0.02 | I29: 2e-05 | J29: 0.35 | K29: 0 | M29: =O29+N29 -> 0.9325 | N29: 0.0125 | O29: 0.92 | P29: 0.08 | Q29: 0.03096595 | R29: 0.072295921 | S29: 0.0025 | T29: 0.0020754516 | U29: 0 | V29: =U29*(500000000/12) -> 0 | W29: PRIME | X29: 0 | Y29: prime | Z29: standard | AA29: 0 | AB29: 0.0425 | AC29: 0.23 | AD29: 1 | AE29: 0.0125
A30: NINP4331 | B30: Unsec Std - 990 - 123 | C30: 123 | D30: 10000 | E30: 990 | F30: 0.0166 | G30: 0.1696 | H30: 0.02 | I30: 2e-05 | J30: 0.35 | K30: 3 | L30: 0.13 | M30: =O30+N30 -> 0.958 | N30: 0.0125 | O30: 0.9455 | P30: 0.0545 | Q30: 0.0166 | R30: 0.074527304 | S30: 0.00955 | T30: 0.00023722492 | U30: 0 | V30: =U30*(500000000/12) -> 0 | W30: PRIME | X30: 0.0363405847853139;0.0425899377937978;0.0510694774208883 | Y30: prime | Z30: hybrid | AA30: 0.0227 | AB30: 0.0242185 | AC30: 0.22 | AD30: 1 | AE30: 0.0125
A31: 990 - 180 | B31: Unsec Std - 990 - 180 | C31: 180 | D31: 10000 | E31: 990 | F31: 0 | G31: 0.1679 | H31: 0.02 | I31: 2e-05 | J31: 0.35 | K31: 0 | M31: =O31+N31 -> 0.9801 | N31: 0.0125 | O31: 0.9676 | P31: 0.0324 | Q31: 0.0207 | R31: 0.070567028 | S31: 0.0628 | T31: 0.086013021 | U31: 0 | V31: =U31*(500000000/12) -> 0 | W31: PRIME | X31: 0 | Y31: prime | Z31: standard | AA31: 0 | AB31: 0.0250635 | AC31: 0.2 | AD31: 1 | AE31: 0.0125
A32: NINP4306 | B32: Unsec Std - 990 - 183 | C32: 183 | D32: 10000 | E32: 990 | F32: 0.0207 | G32: 0.1679 | H32: 0.02 | I32: 2e-05 | J32: 0.35 | K32: 3 | L32: 0.13 | M32: =O32+N32 -> 0.9625 | N32: 0.0125 | O32: 0.95 | P32: 0.05 | Q32: 0.0207 | R32: 0.069040188 | S32: 0.0011 | T32: 0.00075987961 | U32: 0.18 | V32: =U32*(500000000/12) -> 7500000 | W32: PRIME | X32: 0.0363405847853139;0.0425899377937978;0.0510694774208883 | Y32: prime | Z32: hybrid | AA32: 0.0254 | AB32: 0.035647 | AC32: 0.22 | AD32: 1 | AE32: 0.0125
A33: 132 PF | B33: Unsec Std - 999 - 120 | C33: 120 | D33: 10000 | E33: 999 | F33: 0 | G33: 0.261 | H33: 0.02 | I33: 2e-05 | J33: 0.35 | K33: 0 | M33: =O33+N33 -> 1.0074 | N33: 0.0125 | O33: 0.9949 | P33: 0.0051 | Q33: 0.0069 | R33: 0.071521713 | S33: 0.0009 | T33: 0.00065254662 | U33: 0 | V33: =U33*(500000000/12) -> 0 | W33: PRIME | X33: 0 | Y33: prime | Z33: standard | AA33: 0 | AB33: 0.01617 | AC33: 0.30015 | AD33: 1 | AE33: 0.0125
A34: 107PF | B34: Unsec Std - 999 - 180 | C34: 180 | D34: 10000 | E34: 999 | F34: 0 | G34: 0.1995 | H34: 0.02 | I34: 2e-05 | J34: 0.35 | K34: 0 | M34: =O34+N34 -> 0.9983 | N34: 0.0125 | O34: 0.9858 | P34: 0.0142 | Q34: 0.0071 | R34: 0.075407118 | S34: 0.00065 | T34: 0.0012060714 | U34: 0 | V34: =U34*(500000000/12) -> 0 | W34: PRIME | X34: 0 | Y34: prime | Z34: standard | AA34: 0 | AB34: 0.01386 | AC34: 0.20534 | AD34: 1 | AE34: 0.0125
A35: 212PF | B35: Unsec Std - 999 - 60 | C35: 60 | D35: 10000 | E35: 999 | F35: 0 | G35: 0.3087 | H35: 0.02 | I35: 2e-05 | J35: 0.35 | K35: 0 | M35: =O35+N35 -> 0.9772 | N35: 0.0125 | O35: 0.9647 | P35: 0.0353 | Q35: 0.0078 | R35: 0.090334766 | S35: 0.00025 | T35: 0.0009127199 | U35: 0 | V35: =U35*(500000000/12) -> 0 | W35: PRIME | X35: 0 | Y35: prime | Z35: standard | AA35: 0 | AB35: 0.0255925 | AC35: 0.305005 | AD35: 1 | AE35: 0.0125
A36: 158PF | B36: Unsec Std - 999 - 90 | C36: 90 | D36: 10000 | E36: 999 | F36: 0 | G36: 0.304 | H36: 0.02 | I36: 2e-05 | J36: 0.35 | K36: 0 | M36: =O36+N36 -> 1.0017 | N36: 0.0125 | O36: 0.9892 | P36: 0.0108 | Q36: 0.008 | R36: 0.073202394 | S36: 0.0031 | T36: 0.0032475592 | U36: 0 | V36: =U36*(500000000/12) -> 0 | W36: PRIME | X36: 0 | Y36: prime | Z36: standard | AA36: 0 | AB36: 0.02 | AC36: 0.304 | AD36: 1 | AE36: 0.0125
A37: 36EPNI | B37: Unsec Std - EPNI 36 Mo | C37: 36 | D37: 10000 | E37: 0 | F37: 0 | G37: 0.214 | H37: 0.02 | I37: 2e-05 | J37: 0.35 | K37: 36 | M37: =O37+N37 -> 0.8904 | N37: 0.0125 | O37: 0.8779 | P37: 0.1221 | Q37: 0.0111 | R37: 0.067295748 | S37: 0.02495 | T37: 0.018717159 | U37: 0 | V37: =U37*(500000000/12) -> 0 | W37: PRIME | X37: 0 | Y37: prime | Z37: epni | AA37: 0 | AB37: 0.0144375 | AC37: 0.18 | AD37: 1 | AE37: 0.0125
A38: 60EPNI | B38: Unsec Std - EPNI 60 Mo | C38: 60 | D38: 10000 | E38: 0 | F38: 0 | G38: 0.139 | H38: 0.02 | I38: 2e-05 | J38: 0.35 | K38: 60 | M38: =O38+N38 -> 0.8663 | N38: 0.0125 | O38: 0.8538 | P38: 0.1462 | Q38: 0.0103 | R38: 0.044721915 | S38: 0.05535 | T38: 0.063152632 | U38: 0.09 | V38: =U38*(500000000/12) -> 3750000 | W38: PRIME | X38: 0 | Y38: prime | Z38: epni | AA38: 0 | AB38: 0.01386 | AC38: 0.14 | AD38: 1 | AE38: 0.0125
A39: WP18 | B39: 18 Mth WPDI | C39: 58 | D39: 10000 | E39: 2200 | F39: 0.0251 | G39: 0.25701319 | H39: 0.02 | I39: 2e-05 | J39: 0.35 | K39: 18 | L39: 0.82027058 | M39: =O39+N39 -> 0.9592 | N39: 0.0125 | O39: 0.9467 | P39: 0.0533 | Q39: 0.0643 | R39: 0.079462552 | S39: 0.1951 | T39: 0.041090767 | U39: 0.05 | V39: =U39*(500000000/12) -> 2083333.3 | W39: SFY | X39: 0.0652777389894097;0.0356953756194261;0.034058164028278;0.0279406174401888;0.031594188639639;0.0340876225347276;0.0330167624837598;0.0298519380389914;0.0339574704072298;0.0358908101981715;0.0344087960474102;0.0341519438576293;0.0374083860415759;0.0324308183993861;0.0438555113830001;0.0622556562993365;0.0907677106631277;0.123621065918976 | Y39: sfy | Z39: wpdi | AA39: 0.013 | AB39: 0.0643 | AC39: 0.3 | AD39: 1 | AE39: 0.0125
A40: WP6 | B40: 6 Mth WPDI | C40: 56 | D40: 10000 | E40: 2200 | F40: 0.047 | G40: 0.16972991 | H40: 0.02 | I40: 2e-05 | J40: 0.35 | K40: 6 | L40: 0.65464361 | M40: =O40+N40 -> 0.9807 | N40: 0.0125 | O40: 0.9682 | P40: 0.0318 | Q40: 0.0376 | R40: 0.13825132 | S40: 0.003 | T40: 0.0053758171 | U40: 0 | V40: =U40*(500000000/12) -> 0 | W40: SFY | X40: 0.123686189059583;0.0811056604542175;0.08390003415553;0.0705313259374669;0.111422674332577;0.183997727003596 | Y40: sfy | Z40: wpdi | AA40: 0.07 | AB40: 0.0725 | AC40: 0.2 | AD40: 1 | AE40: 0.0125
...

Sheet targets
A1: cdrshock | B1: promo_cdrshock | C1: cprshock | D1: promo_cprshock | E1: target
A2: 1 | B2: 1 | C2: 1 | D2: 1 | E2: 7.5

Sheet Worst Case
A1: Loan Product Variables | B1: loan program | C1: weight (Current) | D1: weight(worst case) | E1: tagging | F1: type
A2: WP18 | B2: 18 Mth WPDI | C2: 0.01295 | D2: 0.05 | E2: PRIME | F2: wpdi
A3: NINP14 | B3: NINP - 14 Mo | C3: 0.0353 | D3: 0.08 | E3: PRIME | F3: ninp
A4: 1190 - 180 | B4: Unsec Std - 1190 - 180 | C4: 0.00185 | D4: 0.07 | E4: PRIME | F4: standard
A5: 1290 - 120 | B5: Unsec Std - 1290 - 120 | C5: 0.0085 | D5: 0.03 | E5: PRIME | F5: standard
A6: NINP4306 | B6: Unsec Std - 990 - 183 | C6: 0.0011 | D6: 0.18 | E6: PRIME | F6: hybrid
A7: 60EPNI | B7: Unsec Std - EPNI 60 Mo | C7: 0.05535 | D7: 0.09 | E7: PRIME | F7: epni
A8: WP18 | B8: 18 Mth WPDI | C8: 0.1951 | D8: 0.05 | E8: SFY | F8: wpdi
A9: NINP12 | B9: NINP - 12 Mo | C9: 0.08485 | D9: 0.13 | E9: SFY | F9: ninp
A10: 1095-120 | B10: Unsec Std - 1095 - 120 | C10: 0.016 | D10: 0.07 | E10: SFY | F10: standard
A11: 1190 - 180 | B11: Unsec Std - 1190 - 180 | C11: 0.00585 | D11: 0.06 | E11: SFY | F11: standard
A12: NINP1399/186 | B12: Unsec Std - 1399 - 186 | C12: 0.00415 | D12: 0.17 | E12: SFY | F12: hybrid
A13: 160PF | B13: Unsec Std - 1490 - 120 | C13: 0.05205 | D13: 0.02 | E13: BD | F13: standard_bd

Sheet Sheet2
A1: loan program | B1: weight | C1: tagging
A2: 18 Mth WPDI | B2: 0.05 | C2: PRIME
A3: NINP - 14 Mo | B3: 0.08 | C3: PRIME
A4: Unsec Std - 1190 - 180 | B4: 0.07 | C4: PRIME
A5: Unsec Std - 1290 - 120 | B5: 0.03 | C5: PRIME
A6: Unsec Std - 990 - 183 | B6: 0.18 | C6: PRIME
A7: Unsec Std - EPNI 60 Mo | B7: 0.09 | C7: PRIME
A8: 18 Mth WPDI | B8: 0.05 | C8: SFY
A9: NINP - 12 Mo | B9: 0.13 | C9: SFY
A10: Unsec Std - 1095 - 120 | B10: 0.07 | C10: SFY
A11: Unsec Std - 1190 - 180 | B11: 0.06 | C11: SFY
A12: Unsec Std - 1399 - 186 | B12: 0.17 | C12: SFY
A13: Unsec Std - 1490 - 120 | B13: 0.02 | C13: SFY

Sheet Sheet1
A1: Loan program | B1: platform | C1: Loan Product Variables | D1: Term of Loan in Mths (total) | E1: Avg Loan Size $'s | F1: Loan Interest Rate | G1: CDR - Promotion Period Only | H1: Constant Prepay Rate | I1: Servicing Fees | J1: Late Fees% UPB/Mth | K1: Default Recovery % | L1: Promotional Period Term | M1: Promo Period Prepayment | N1: SFC Selling Price | O1: SFC Loan Margin | P1: SFC Purchase Price | Q1: Merchant Discount | R1: CDR No Promo or Post Promo | S1: Single Pool Net Loan Yield | T1: weight
A2: =VLOOKUP(C2,portfolio_7_50!$A$2:$B$38,2,FALSE) -> 12 Mth WPDI | B2: PRIME | C2: WP12 | D2: 58 | E2: 10000 | F2: 0.2136 | G2: 0.0247 | H2: 0.2803 | I2: 0.02 | J2: 2e-05 | K2: 0.35 | L2: 12 | M2: 0.75340353 | N2: 0.955 | O2: 0.0125 | P2: 0.9425 | Q2: 0.0575 | R2: 0.0391 | S2: 0.12920518 | T2: 0.025342194
A3: =VLOOKUP(C3,portfolio_7_50!$A$2:$B$38,2,FALSE) -> 12 Mth WPDI - 2395 | B3: PRIME | C3: WP12-2395 | D3: 58 | E3: 10000 | F3: 0.2022 | G3: 0.0312 | H3: 0.236 | I3: 0.02 | J3: 2e-05 | K3: 0.35 | L3: 12 | M3: 0.75340353 | N3: 0.9675 | O3: 0.0125 | P3: 0.955 | Q3: 0.045 | R3: 0.0312 | S3: 0.10617216 | T3: 0.0036001694
A4: =VLOOKUP(C4,portfolio_7_50!$A$2:$B$38,2,FALSE) -> 18 Mth WPDI | B4: PRIME | C4: WP18 | D4: 59 | E4: 10000 | F4: 0.2136 | G4: 0.0186 | H4: 0.2705 | I4: 0.02 | J4: 2e-05 | K4: 0.35 | L4: 18 | M4: 0.78556326 | N4: 0.9595 | O4: 0.0125 | P4: 0.947 | Q4: 0.053 | R4: 0.0531 | S4: 0.096218476 | T4: 0.012974055
A5: =VLOOKUP(C5,portfolio_7_50!$A$2:$B$38,2,FALSE) -> 18 Mth WPDI - 2395 | B5: PRIME | C5: WP18-2395 | D5: 58 | E5: 10000 | F5: 0.2022 | G5: 0.0158 | H5: 0.2591 | I5: 0.02 | J5: 2e-05 | K5: 0.35 | L5: 18 | M5: 0.78556326 | N5: 0.9425 | O5: 0.0125 | P5: 0.93 | Q5: 0.07 | R5: 0.0438 | S5: 0.11215601 | T5: 0.00035236354
A6: =VLOOKUP(C6,portfolio_7_50!$A$2:$B$38,2,FALSE) -> 24 Mth WPDI | B6: PRIME | C6: WP24 | D6: 59 | E6: 10000 | F6: 0.2136 | G6: 0.0291 | H6: 0.1948 | I6: 0.02 | J6: 2e-05 | K6: 0.35 | L6: 24 | M6: 0.81138877 | N6: 0.9292 | O6: 0.0125 | P6: 0.9167 | Q6: 0.0833 | R6: 0.0123 | S6: 0.1032113 | T6: 0.0012781294
A7: =VLOOKUP(C7,portfolio_7_50!$A$2:$B$38,2,FALSE) -> 24 Mth WPDI - 2395 | B7: PRIME | C7: WP24-2395 | D7: 58 | E7: 10000 | F7: 0.1931 | G7: 0.0199 | H7: 0.1607 | I7: 0.02 | J7: 2e-05 | K7: 0.35 | L7: 24 | M7: 0.81138877 | N7: 0.9225 | O7: 0.0125 | P7: 0.91 | Q7: 0.09 | R7: 0.0226 | S7: 0.10872926 | T7: 0.00037542522
A8: =VLOOKUP(C8,portfolio_7_50!$A$2:$B$38,2,FALSE) -> 6 Mth WPDI | B8: PRIME | C8: WP6 | D8: 57 | E8: 10000 | F8: 0.2136 | G8: 0.0601 | H8: 0.2243 | I8: 0.02 | J8: 2e-05 | K8: 0.35 | L8: 6 | M8: 0.60178709 | N8: 0.9779 | O8: 0.0125 | P8: 0.9654 | Q8: 0.0346 | R8: 0.0213 | S8: 0.14802476 | T8: 0.0033073657
A9: =VLOOKUP(C9,portfolio_7_50!$A$2:$B$38,2,FALSE) -> NINP - 10 Mo | B9: PRIME | C9: NINP10 | D9: 85 | E9: 10000 | F9: 0.2145 | G9: 0.0155 | H9: 0.4075 | I9: 0.02 | J9: 2e-05 | K9: 0.35 | L9: 10 | M9: 0.7703 | N9: 0.9579 | O9: 0.0125 | P9: 0.9454 | Q9: 0.0546 | R9: 0.049 | S9: 0.077643508 | T9: 0.15837443
A10: =VLOOKUP(C10,portfolio_7_50!$A$2:$B$38,2,FALSE) -> NINP - 14 Mo | B10: PRIME | C10: NINP14 | D10: 92 | E10: 10000 | F10: 0.2145 | G10: 0.0133 | H10: 0.336 | I10: 0.02 | J10: 2e-05 | K10: 0.35 | L10: 14 | M10: 0.7754 | N10: 0.9383 | O10: 0.0125 | P10: 0.9258 | Q10: 0.0742 | R10: 0.0647 | S10: 0.075389505 | T10: 0.035280659
A11: =VLOOKUP(C11,portfolio_7_50!$A$2:$B$38,2,FALSE) -> NINP - 20 Mo | B11: PRIME | C11: NINP20 | D11: 99 | E11: 10000 | F11: 0.2145 | G11: 0.0114 | H11: 0.3365 | I11: 0.02 | J11: 2e-05 | K11: 0.35 | L11: 20 | M11: 0.7803 | N11: 0.8973 | O11: 0.0125 | P11: 0.8848 | Q11: 0.1152 | R11: 0.0726 | S11: 0.082151175 | T11: 0.0065838722
A12: =VLOOKUP(C12,portfolio_7_50!$A$2:$B$38,2,FALSE) -> NINP - 24 Mo | B12: PRIME | C12: NINP24 | D12: 96 | E12: 10000 | F12: 0.2399 | G12: 0.0052 | H12: 0.5 | I12: 0.02 | J12: 2e-05 | K12: 0.35 | L12: 24 | M12: 0.8836 | N12: 0.8989 | O12: 0.0125 | P12: 0.8864 | Q12: 0.1136 | R12: 0.0052 | S12: 0.071474241 | T12: 0.013515101
A13: =VLOOKUP(C13,portfolio_7_50!$A$2:$B$38,2,FALSE) -> Unsec Std - 1090 - 120 | B13: PRIME | C13: 1090 - 120 | D13: 120 | E13: 10000 | F13: 0.109 | G13: 0 | H13: 0.16959519 | I13: 0.02 | J13: 2e-05 | K13: 0.35 | L13: 0 | M13: 0 | N13: 1.0072 | O13: 0.0125 | P13: 0.9947 | Q13: 0.0053 | R13: 0.0166 | S13: 0.074356817 | T13: 0.0084427837
... A38: =VLOOKUP(C38,portfolio_7_50!$A$2:$B$38,2,FALSE) -> Unsec Std - EPNI 60 Mo | B38: PRIME | C38: 60EPNI | D38: 60 | E38: 10000 | F38: 0 | G38: 0 | H38: 0.139 | I38: 0.02 | J38: 2e-05 | K38: 0.35 | L38: 0 | M38: 0 | N38: 0.8663 | O38: 0.0125 | P38: 0.8538 | Q38: 0.1462 | R38: 0.0103 | S38: 0.044721915 | T38: 0.055363942
A39: =VLOOKUP(C39,portfolio_7_50!$A$39:$B$54,2,FALSE) -> 18 Mth WPDI | B39: SFY | C39: WP18 | D39: 58 | E39: 10000 | F39: 0.22 | G39: 0.0251 | H39: 0.25701319 | I39: 0.02 | J39: 2e-05 | K39: 0.35 | L39: 18 | M39: 0.82027058 | N39: 0.9592 | O39: 0.0125 | P39: 0.9467 | Q39: 0.0533 | R39: 0.0643 | S39: 0.079462552 | T39: 0.19510774
A40: =VLOOKUP(C40,portfolio_7_50!$A$39:$B$54,2,FALSE) -> 6 Mth WPDI | B40: SFY | C40: WP6 | D40: 56 | E40: 10000 | F40: 0.22 | G40: 0.047 | H40: 0.16972991 | I40: 0.02 | J40: 2e-05 | K40: 0.35 | L40: 6 | M40: 0.65464361 | N40: 0.9807 | O40: 0.0125 | P40: 0.9682 | Q40: 0.0318 | R40: 0.0376 | S40: 0.13825132 | T40: 0.003011883
A41: =VLOOKUP(C41,portfolio_7_50!$A$39:$B$54,2,FALSE) -> NINP - 10 Mo | B41: SFY | C41: NINP10 | D41: 86 | E41: 10000 | F41: 0.22 | G41: 0.013395681 | H41: 0.3347 | I41: 0.02 | J41: 2e-05 | K41: 0.35 | L41: 10 | M41: 0.825 | N41: 0.9565 | O41: 0.0125 | P41: 0.944 | Q41: 0.056 | R41: 0.013395681 | S41: 0.08809352 | T41: 0.014922624
A42: =VLOOKUP(C42,portfolio_7_50!$A$39:$B$54,2,FALSE) -> NINP - 12 Mo | B42: SFY | C42: NINP12 | D42: 86 | E42: 10000 | F42: 0.22 | G42: 0.0076956887 | H42: 0.5 | I42: 0.02 | J42: 2e-05 | K42: 0.35 | L42: 12 | M42: 0.9704 | N42: 0.9568 | O42: 0.0125 | P42: 0.9443 | Q42: 0.0557 | R42: 0.0076956887 | S42: 0.046832993 | T42: 0.084825586
A43: =VLOOKUP(C43,portfolio_7_50!$A$39:$B$54,2,FALSE) -> NINP - 20 Mo | B43: SFY | C43: NINP20 | D43: 96 | E43: 10000 | F43: 0.22 | G43: 0.013222634 | H43: 0.2719 | I43: 0.02 | J43: 2e-05 | K43: 0.35 | L43: 20 | M43: 0.884 | N43: 0.8949 | O43: 0.0125 | P43: 0.8824 | Q43: 0.1176 | R43: 0.013222634 | S43: 0.082671503 | T43: 0.0085244582
A44: =VLOOKUP(C44,portfolio_7_50!$A$39:$B$54,2,FALSE) -> NINP - 24 Mo | B44: SFY | C44: NINP24 | D44: 96 | E44: 10000 | F44: 0.22 | G44: 0.0080796899 | H44: 0.5 | I44: 0.02 | J44: 2e-05 | K44: 0.35 | L44: 24 | M44: 0.8836 | N44: 0.8961 | O44: 0.0125 | P44: 0.8836 | Q44: 0.1164 | R44: 0.0080796899 | S44: 0.069662236 | T44: 0.060346685
A45: =VLOOKUP(C45,portfolio_7_50!$A$39:$B$54,2,FALSE) -> Unsec Std - 1090 - 180 | B45: SFY | C45: 1090 - 180 | D45: 180 | E45: 10000 | F45: 0.109 | G45: 0 | H45: 0.18665108 | I45: 0.02 | J45: 2e-05 | K45: 0.35 | L45: 0 | M45: 0 | N45: 0.983 | O45: 0.012485761 | P45: 0.97051424 | Q45: 0.029485761 | R45: 0.0086141513 | S45: 0.088625485 | T45: 0.0060510577
A46: =VLOOKUP(C46,portfolio_7_50!$A$39:$B$54,2,FALSE) -> Unsec Std - 1095 - 120 | B46: SFY | C46: 1095-120 | D46: 120 | E46: 10000 | F46: 0.1095 | G46: 0 | H46: 0.2 | I46: 0.02 | J46: 2e-05 | K46: 0.35 | L46: 0 | M46: 0 | N46: 1.0025 | O46: 0.0125 | P46: 0.99 | Q46: 0.01 | R46: 0.0497 | S46: 0.052880451 | T46: 0.016021847
A47: =VLOOKUP(C47,portfolio_7_50!$A$39:$B$54,2,FALSE) -> Unsec Std - 1190 - 120 | B47: SFY | C47: 1190 - 120 | D47: 120 | E47: 10000 | F47: 0.119 | G47: 0 | H47: 0.25316223 | I47: 0.02 | J47: 2e-05 | K47: 0.35 | L47: 0 | M47: 0 | N47: 1.0042 | O47: 0.012534858 | P47: 0.99166514 | Q47: 0.008334858 | R47: 0.038765744 | S47: 0.068913732 | T47: 0.010752228
A48: =VLOOKUP(C48,portfolio_7_50!$A$39:$B$54,2,FALSE) -> Unsec Std - 1190 - 180 | B48: SFY | C48: 1190 - 180 | D48: 180 | E48: 10000 | F48: 0.119 | G48: 0 | H48: 0.18672372 | I48: 0.02 | J48: 2e-05 | K48: 0.35 | L48: 0 | M48: 0 | N48: 0.9757 | O48: 0.012456242 | P48: 0.96324376 | Q48: 0.036756242 | R48: 0.030122208 | S48: 0.085709191 | T48: 0.0058379766
A49: =VLOOKUP(C49,portfolio_7_50!$A$39:$B$54,2,FALSE) -> Unsec Std - 1199 - 186 | B49: SFY | C49: NINP1199/186 | D49: 186 | E49: 10000 | F49: 0.1199 | G49: 0.0171288 | H49: 0.23 | I49: 0.02 | J49: 2e-05 | K49: 0.15 | L49: 6 | M49: 0.39420057 | N49: 0.985 | O49: 0.0125 | P49: 0.9725 | Q49: 0.0275 | R49: 0.0171288 | S49: 0.066067704 | T49: 0.00037010295
A50: =VLOOKUP(C50,portfolio_7_50!$A$39:$B$54,2,FALSE) -> Unsec Std - 1249 - 186 | B50: SFY | C50: NINP1249-186 | D50: 186 | E50: 10000 | F50: 0.1249 | G50: 0.0244 | H50: 0.23 | I50: 0.02 | J50: 2e-05 | K50: 0.15 | L50: 6 | M50: 0.39420057 | N50: 0.985 | O50: 0.0125 | P50: 0.9725 | Q50: 0.0275 | R50: 0.0171288 | S50: 0.068433102 | T50: 0.00010058032
... A54: =VLOOKUP(C54,portfolio_7_50!$A$39:$B$54,2,FALSE) -> Unsec Std - 999 - 120 | B54: SFY | C54: 132 PF | D54: 120 | E54: 10000 | F54: 0.0999 | G54: 0 | H54: 0.261 | I54: 0.02 | J54: 2e-05 | K54: 0.35 | L54: 0 | M54: 0 | N54: 1.0107 | O54: 0.012501672 | P54: 0.99819833 | Q54: 0.0018016717 | R54: 0.0082286174 | S54: 0.069054697 | T54: 0.031593202
