Workbook

Sheet Sheet1
A1: loan program | B1: promo_term | C1: platform | D1: tagging | E1: servicing_cost | F1: irr_support | G1: type | H1: late_percent | I1: recovery_percent | J1: modeled_purchase_price | K1: new_programs | L1: proposed_cdr_promo | M1: proposed_cdr_promo_old | N1: proposed_cdr | O1: proposed_cdr_old | P1: proposed_cpr | Q1: proposed_promo_cpr_percent | R1: constant_cpr | S1: constant_cpr_old | T1: cdr_promo | U1: cdr_promo_old | V1: cdr | W1: cdr_old | X1: yield | Y1: cpr | Z1: cpr_old | AA1: loan_term | AB1: coupon
A2: Unsec Std - 1049 - 132 | B2: 12 | C2: prime | D2: PRIME | E2: 0.0165 | F2: 0.0115 | G2: hybrid | H2: 2e-05 | I2: 0.15 | J2: 0.9825 | K2: TRUE | L2: =T2*1.3 -> 0.013044096 | M2: 0.013044096 | N2: =V2*1.3 -> 0.013044096 | O2: 0.013044096 | P2: =R2*1.15 -> 0.2645 | Q2: 1 | R2: 0.23 | S2: 0.23 | T2: 0.01003392 | U2: 0.01003392 | V2: 0.01003392 | W2: 0.01003392 | X2: 0.060852269 | Y2: 0.034087798153406;0.029131872311023;0.029131872311023;0.025455429050157;0.025455429050157;0.024935476432192;0.024935476432192;0.0330338174243784;0.0330338174243784;0.052503321664899;0.0723270250344311;0.115968664711763 | Z2: 0.034087798153406;0.029131872311023;0.029131872311023;0.025455429050157;0.025455429050157;0.024935476432192;0.024935476432192;0.0330338174243784;0.0330338174243784;0.052503321664899;0.0723270250344311;0.115968664711763 | AA2: 132 | AB2: 1049
A3: Unsec Std - 1049 - 186 | B3: 6 | C3: prime | D3: PRIME | E3: 0.0165 | F3: 0.0115 | G3: hybrid | H3: 2e-05 | I3: 0.15 | J3: 0.9925 | K3: TRUE | L3: =T3*1.3 -> 0.011628552 | M3: 0.011628552 | N3: =V3*1.3 -> 0.011628552 | O3: 0.011628552 | P3: =R3*1.15 -> 0.2645 | Q3: 1 | R3: 0.23 | S3: 0.23 | T3: 0.00894504 | U3: 0.00894504 | V3: 0.00894504 | W3: 0.00894504 | X3: 0.07753936 | Y3: 0.0489849142849816;0.0428030164624041;0.0419287220074737;0.0555459909257746;0.0882837424238861;0.116654180496246 | Z3: 0.0489849142849816;0.0428030164624041;0.0419287220074737;0.0555459909257746;0.0882837424238861;0.116654180496246 | AA3: 186 | AB3: 1049
A4: Unsec Std - 1049 - 63 | B4: 3 | C4: prime | D4: PRIME | E4: 0.0165 | F4: 0.0115 | G4: hybrid | H4: 2e-05 | I4: 0.15 | J4: 1.005 | K4: TRUE | L4: =T4*1.3 -> 0.014212224 | M4: 0.014212224 | N4: =V4*1.3 -> 0.014212224 | O4: 0.014212224 | P4: =R4*1.15 -> 0.2645 | Q4: 1 | R4: 0.23 | S4: 0.23 | T4: 0.01093248 | U4: 0.01093248 | V4: 0.01093248 | W4: 0.01093248 | X4: 0.076511354 | Y4: 0.0436711592742046;0.051181123470062;0.0613711445667025 | Z4: 0.0436711592742046;0.051181123470062;0.0613711445667025 | AA4: 63 | AB4: 1049
A5: Unsec Std - 1099 / 132 | B5: 12 | C5: prime | D5: PRIME | E5: 0.0165 | F5: 0.0115 | G5: hybrid | H5: 2e-05 | I5: 0.15 | J5: 0.9825 | K5: TRUE | L5: =T5*1.3 -> 0.013044096 | M5: 0.013044096 | N5: =V5*1.3 -> 0.013044096 | O5: 0.013044096 | P5: =R5*1.15 -> 0.2645 | Q5: 1 | R5: 0.23 | S5: 0.23 | T5: 0.01003392 | U5: 0.01003392 | V5: 0.01003392 | W5: 0.01003392 | X5: 0.063656481 | Y5: 0.034087798153406;0.029131872311023;0.029131872311023;0.025455429050157;0.025455429050157;0.024935476432192;0.024935476432192;0.0330338174243784;0.0330338174243784;0.052503321664899;0.0723270250344311;0.115968664711763 | Z5: 0.034087798153406;0.029131872311023;0.029131872311023;0.025455429050157;0.025455429050157;0.024935476432192;0.024935476432192;0.0330338174243784;0.0330338174243784;0.052503321664899;0.0723270250344311;0.115968664711763 | AA5: 132 | AB5: 1099
A6: Unsec Std - 1099 / 186 | B6: 6 | C6: prime | D6: PRIME | E6: 0.0165 | F6: 0.0115 | G6: hybrid | H6: 2e-05 | I6: 0.15 | J6: 0.9925 | K6: TRUE | L6: =T6*1.3 -> 0.011628552 | M6: 0.011628552 | N6: =V6*1.3 -> 0.011628552 | O6: 0.011628552 | P6: =R6*1.15 -> 0.2645 | Q6: 1 | R6: 0.23 | S6: 0.23 | T6: 0.00894504 | U6: 0.00894504 | V6: 0.00894504 | W6: 0.00894504 | X6: 0.081311552 | Y6: 0.0489849142849816;0.0428030164624041;0.0419287220074737;0.0555459909257746;0.0882837424238861;0.116654180496246 | Z6: 0.0489849142849816;0.0428030164624041;0.0419287220074737;0.0555459909257746;0.0882837424238861;0.116654180496246 | AA6: 186 | AB6: 1099
A7: Unsec Std - 1099 / 63 | B7: 3 | C7: prime | D7: PRIME | E7: 0.0165 | F7: 0.0115 | G7: hybrid | H7: 2e-05 | I7: 0.15 | J7: 1.005 | K7: TRUE | L7: =T7*1.3 -> 0.014212224 | M7: 0.014212224 | N7: =V7*1.3 -> 0.014212224 | O7: 0.014212224 | P7: =R7*1.15 -> 0.2645 | Q7: 1 | R7: 0.23 | S7: 0.23 | T7: 0.01093248 | U7: 0.01093248 | V7: 0.01093248 | W7: 0.01093248 | X7: 0.080697011 | Y7: 0.0436711592742046;0.051181123470062;0.0613711445667025 | Z7: 0.0436711592742046;0.051181123470062;0.0613711445667025 | AA7: 63 | AB7: 1099
A8: Unsec Std - 1149 - 132 | B8: 12 | C8: prime | D8: PRIME | E8: 0.0165 | F8: 0.0115 | G8: hybrid | H8: 2e-05 | I8: 0.15 | J8: 0.9825 | K8: TRUE | L8: =T8*1.3 -> 0.01872 | M8: 0.01872 | N8: =V8*1.3 -> 0.013044096 | O8: 0.013044096 | P8: =R8*1.15 -> 0.2645 | Q8: 1 | R8: 0.23 | S8: 0.23 | T8: 0.0144 | U8: 0.0144 | V8: 0.01003392 | W8: 0.01003392 | X8: 0.064808875 | Y8: 0.034087798153406;0.029131872311023;0.029131872311023;0.025455429050157;0.025455429050157;0.024935476432192;0.024935476432192;0.0330338174243784;0.0330338174243784;0.052503321664899;0.0723270250344311;0.115968664711763 | Z8: 0.034087798153406;0.029131872311023;0.029131872311023;0.025455429050157;0.025455429050157;0.024935476432192;0.024935476432192;0.0330338174243784;0.0330338174243784;0.052503321664899;0.0723270250344311;0.115968664711763 | AA8: 132 | AB8: 1149
A9: Unsec Std - 1149 - 186 | B9: 6 | C9: prime | D9: PRIME | E9: 0.0165 | F9: 0.0115 | G9: hybrid | H9: 2e-05 | I9: 0.15 | J9: 0.9925 | K9: TRUE | L9: =T9*1.3 -> 0.01703 | M9: 0.01703 | N9: =V9*1.3 -> 0.011628552 | O9: 0.011628552 | P9: =R9*1.15 -> 0.2645 | Q9: 1 | R9: 0.23 | S9: 0.23 | T9: 0.0131 | U9: 0.0131 | V9: 0.00894504 | W9: 0.00894504 | X9: 0.084249886 | Y9: 0.0489849142849816;0.0428030164624041;0.0419287220074737;0.0555459909257746;0.0882837424238861;0.116654180496246 | Z9: 0.0489849142849816;0.0428030164624041;0.0419287220074737;0.0555459909257746;0.0882837424238861;0.116654180496246 | AA9: 186 | AB9: 1149
A10: Unsec Std - 1149 - 63 | B10: 3 | C10: prime | D10: PRIME | E10: 0.0165 | F10: 0.0115 | G10: hybrid | H10: 2e-05 | I10: 0.15 | J10: 1.005 | K10: TRUE | L10: =T10*1.3 -> 0.02028 | M10: 0.02028 | N10: =V10*1.3 -> 0.014212224 | O10: 0.014212224 | P10: =R10*1.15 -> 0.2645 | Q10: 1 | R10: 0.23 | S10: 0.23 | T10: 0.0156 | U10: 0.0156 | V10: 0.01093248 | W10: 0.01093248 | X10: 0.08426103 | Y10: 0.0436711592742046;0.051181123470062;0.0613711445667025 | Z10: 0.0436711592742046;0.051181123470062;0.0613711445667025 | AA10: 63 | AB10: 1149
A11: Unsec Std - 1199 / 132 | B11: 12 | C11: prime | D11: PRIME | E11: 0.0165 | F11: 0.0115 | G11: hybrid | H11: 2e-05 | I11: 0.15 | J11: 0.9825 | K11: TRUE | L11: =T11*1.3 -> 0.012070656 | M11: 0.012070656 | N11: =V11*1.3 -> 0.012070656 | O11: 0.012070656 | P11: =R11*1.15 -> 0.2645 | Q11: 1 | R11: 0.23 | S11: 0.23 | T11: 0.00928512 | U11: 0.00928512 | V11: 0.00928512 | W11: 0.00928512 | X11: 0.069913491 | Y11: 0.034087798153406;0.029131872311023;0.029131872311023;0.025455429050157;0.025455429050157;0.024935476432192;0.024935476432192;0.0330338174243784;0.0330338174243784;0.052503321664899;0.0723270250344311;0.115968664711763 | Z11: 0.034087798153406;0.029131872311023;0.029131872311023;0.025455429050157;0.025455429050157;0.024935476432192;0.024935476432192;0.0330338174243784;0.0330338174243784;0.052503321664899;0.0723270250344311;0.115968664711763 | AA11: 132 | AB11: 1199
A12: Unsec Std - 1199 / 186 | B12: 6 | C12: prime | D12: PRIME | E12: 0.0165 | F12: 0.0115 | G12: hybrid | H12: 2e-05 | I12: 0.15 | J12: 0.9925 | K12: TRUE | L12: =T12*1.3 -> 0.011097216 | M12: 0.011097216 | N12: =V12*1.3 -> 0.011097216 | O12: 0.011097216 | P12: =R12*1.15 -> 0.2645 | Q12: 1 | R12: 0.23 | S12: 0.23 | T12: 0.00853632 | U12: 0.00853632 | V12: 0.00853632 | W12: 0.00853632 | X12: 0.089186274 | Y12: 0.0489849142849816;0.0428030164624041;0.0419287220074737;0.0555459909257746;0.0882837424238861;0.116654180496246 | Z12: 0.0489849142849816;0.0428030164624041;0.0419287220074737;0.0555459909257746;0.0882837424238861;0.116654180496246 | AA12: 186 | AB12: 1199
A13: Unsec Std - 1199 / 63 | B13: 3 | C13: prime | D13: PRIME | E13: 0.0165 | F13: 0.0115 | G13: hybrid | H13: 2e-05 | I13: 0.15 | J13: 1.005 | K13: TRUE | L13: =T13*1.3 -> 0.012265344 | M13: 0.012265344 | N13: =V13*1.3 -> 0.012265344 | O13: 0.012265344 | P13: =R13*1.15 -> 0.2645 | Q13: 1 | R13: 0.23 | S13: 0.23 | T13: 0.00943488 | U13: 0.00943488 | V13: 0.00943488 | W13: 0.00943488 | X13: 0.090397598 | Y13: 0.0436711592742046;0.051181123470062;0.0613711445667025 | Z13: 0.0436711592742046;0.051181123470062;0.0613711445667025 | AA13: 63 | AB13: 1199
... A26: Unsec Std - 1449 - 63 | B26: 3 | C26: prime | D26: PRIME | E26: 0.0165 | F26: 0.0115 | G26: hybrid | H26: 2e-05 | I26: 0.15 | J26: 1.005 | K26: TRUE | L26: =T26*1.3 -> 0.05434 | M26: 0.05434 | N26: =V26*1.3 -> 0.024950159 | O26: 0.024950159 | P26: =R26*1.15 -> 0.2645 | Q26: 1 | R26: 0.23 | S26: 0.23 | T26: 0.0418 | U26: 0.0418 | V26: 0.01919243 | W26: 0.01919243 | X26: 0.099288061 | Y26: 0.0436711592742046;0.051181123470062;0.0613711445667025 | Z26: 0.0436711592742046;0.051181123470062;0.0613711445667025 | AA26: 63 | AB26: 1449
A27: Unsec Std - 399 - 60 | B27: 0 | C27: prime | D27: PRIME | E27: 0.0165 | F27: 0.0115 | G27: standard | H27: 2e-05 | I27: 0.15 | J27: 0.93 | K27: TRUE | L27: =T27*1.3 -> 0 | M27: 0 | N27: =V27*1.3 -> 0.0182 | O27: 0.0182 | P27: =R27*1.15 -> 0.115 | Q27: 1 | R27: 0.1 | S27: 0.1 | T27: 0 | U27: 0 | V27: 0.014 | W27: 0.014 | X27: 0.04576961 | Y27: 0 | Z27: 0 | AA27: 60 | AB27: 399
A28: Unsec Std - 399 - 84 | B28: 0 | C28: prime | D28: PRIME | E28: 0.0165 | F28: 0.0115 | G28: standard | H28: 2e-05 | I28: 0.15 | J28: 0.92 | K28: TRUE | L28: =T28*1.3 -> 0 | M28: 0 | N28: =V28*1.3 -> 0.0182 | O28: 0.0182 | P28: =R28*1.15 -> 0.115 | Q28: 1 | R28: 0.1 | S28: 0.1 | T28: 0 | U28: 0 | V28: 0.014 | W28: 0.014 | X28: 0.041813838 | Y28: 0 | Z28: 0 | AA28: 84 | AB28: 399
A29: Unsec Std - 649 - 132 | B29: 12 | C29: prime | D29: PRIME | E29: 0.0165 | F29: 0.0115 | G29: hybrid | H29: 2e-05 | I29: 0.15 | J29: 0.9825 | K29: TRUE | L29: =T29*1.3 -> 0.00754 | M29: 0.00754 | N29: =V29*1.3 -> 0.0060032177 | O29: 0.0060032177 | P29: =R29*1.15 -> 0.2645 | Q29: 1 | R29: 0.23 | S29: 0.23 | T29: 0.0058 | U29: 0.0058 | V29: 0.0046178598 | W29: 0.0046178598 | X29: 0.042425322 | Y29: 0.034087798153406;0.029131872311023;0.029131872311023;0.025455429050157;0.025455429050157;0.024935476432192;0.024935476432192;0.0330338174243784;0.0330338174243784;0.052503321664899;0.0723270250344311;0.115968664711763 | Z29: 0.034087798153406;0.029131872311023;0.029131872311023;0.025455429050157;0.025455429050157;0.024935476432192;0.024935476432192;0.0330338174243784;0.0330338174243784;0.052503321664899;0.0723270250344311;0.115968664711763 | AA29: 132 | AB29: 649
A30: Unsec Std - 649 - 186 | B30: 6 | C30: prime | D30: PRIME | E30: 0.0165 | F30: 0.0115 | G30: hybrid | H30: 2e-05 | I30: 0.15 | J30: 0.9925 | K30: TRUE | L30: =T30*1.3 -> 0.0056784 | M30: 0.0056784 | N30: =V30*1.3 -> 0.0056784 | O30: 0.0056784 | P30: =R30*1.15 -> 0.2645 | Q30: 1 | R30: 0.23 | S30: 0.23 | T30: 0.004368 | U30: 0.004368 | V30: 0.004368 | W30: 0.004368 | X30: 0.050952089 | Y30: 0.0489849142849816;0.0428030164624041;0.0419287220074737;0.0555459909257746;0.0882837424238861;0.116654180496246 | Z30: 0.0489849142849816;0.0428030164624041;0.0419287220074737;0.0555459909257746;0.0882837424238861;0.116654180496246 | AA30: 186 | AB30: 649
A31: Unsec Std - 699 / 186 | B31: 6 | C31: prime | D31: PRIME | E31: 0.0165 | F31: 0.0115 | G31: hybrid | H31: 2e-05 | I31: 0.15 | J31: 0.9925 | K31: TRUE | L31: =T31*1.3 -> 0.0056784 | M31: 0.0056784 | N31: =V31*1.3 -> 0.0056784 | O31: 0.0056784 | P31: =R31*1.15 -> 0.2645 | Q31: 1 | R31: 0.23 | S31: 0.23 | T31: 0.004368 | U31: 0.004368 | V31: 0.004368 | W31: 0.004368 | X31: 0.054827875 | Y31: 0.0489849142849816;0.0428030164624041;0.0419287220074737;0.0555459909257746;0.0882837424238861;0.116654180496246 | Z31: 0.0489849142849816;0.0428030164624041;0.0419287220074737;0.0555459909257746;0.0882837424238861;0.116654180496246 | AA31: 186 | AB31: 699
A32: Unsec Std - 749 - 186 | B32: 6 | C32: prime | D32: PRIME | E32: 0.0165 | F32: 0.0115 | G32: hybrid | H32: 2e-05 | I32: 0.15 | J32: 0.9925 | K32: TRUE | L32: =T32*1.3 -> 0.00689 | M32: 0.00689 | N32: =V32*1.3 -> 0.0056784 | O32: 0.0056784 | P32: =R32*1.15 -> 0.2645 | Q32: 1 | R32: 0.23 | S32: 0.23 | T32: 0.0053 | U32: 0.0053 | V32: 0.004368 | W32: 0.004368 | X32: 0.058518074 | Y32: 0.0489849142849816;0.0428030164624041;0.0419287220074737;0.0555459909257746;0.0882837424238861;0.116654180496246 | Z32: 0.0489849142849816;0.0428030164624041;0.0419287220074737;0.0555459909257746;0.0882837424238861;0.116654180496246 | AA32: 186 | AB32: 749
A33: Unsec Std - 849 - 120 | B33: 0 | C33: prime | D33: PRIME | E33: 0.0165 | F33: 0.0115 | G33: standard | H33: 2e-05 | I33: 0.15 | J33: 0.9825 | K33: TRUE | L33: =T33*1.3 -> 0 | M33: 0 | N33: =V33*1.3 -> 0.0364 | O33: 0.0364 | P33: =R33*1.15 -> 0.138 | Q33: 1 | R33: 0.12 | S33: 0.12 | T33: 0 | U33: 0 | V33: 0.028 | W33: 0.028 | X33: 0.065878879 | Y33: 0 | Z33: 0 | AA33: 120 | AB33: 849
A34: Unsec Std - 849 - 132 | B34: 12 | C34: prime | D34: PRIME | E34: 0.0165 | F34: 0.0115 | G34: hybrid | H34: 2e-05 | I34: 0.15 | J34: 0.9825 | K34: TRUE | L34: =T34*1.3 -> 0.0060032177 | M34: 0.0060032177 | N34: =V34*1.3 -> 0.0060032177 | O34: 0.0060032177 | P34: =R34*1.15 -> 0.2645 | Q34: 1 | R34: 0.23 | S34: 0.23 | T34: 0.0046178598 | U34: 0.0046178598 | V34: 0.0046178598 | W34: 0.0046178598 | X34: 0.054357781 | Y34: 0.034087798153406;0.029131872311023;0.029131872311023;0.025455429050157;0.025455429050157;0.024935476432192;0.024935476432192;0.0330338174243784;0.0330338174243784;0.052503321664899;0.0723270250344311;0.115968664711763 | Z34: 0.034087798153406;0.029131872311023;0.029131872311023;0.025455429050157;0.025455429050157;0.024935476432192;0.024935476432192;0.0330338174243784;0.0330338174243784;0.052503321664899;0.0723270250344311;0.115968664711763 | AA34: 132 | AB34: 849
A35: Unsec Std - 849 - 180 | B35: 0 | C35: prime | D35: PRIME | E35: 0.0165 | F35: 0.0115 | G35: standard | H35: 2e-05 | I35: 0.15 | J35: 0.9825 | K35: TRUE | L35: =T35*1.3 -> 0 | M35: 0 | N35: =V35*1.3 -> 0.0364 | O35: 0.0364 | P35: =R35*1.15 -> 0.138 | Q35: 1 | R35: 0.12 | S35: 0.12 | T35: 0 | U35: 0 | V35: 0.028 | W35: 0.028 | X35: 0.064873162 | Y35: 0 | Z35: 0 | AA35: 180 | AB35: 849
A36: Unsec Std - 849 - 63 | B36: 3 | C36: prime | D36: PRIME | E36: 0.0165 | F36: 0.0115 | G36: hybrid | H36: 2e-05 | I36: 0.15 | J36: 1.005 | K36: TRUE | L36: =T36*1.3 -> 0.0053361935 | M36: 0.0053361935 | N36: =V36*1.3 -> 0.0053361935 | O36: 0.0053361935 | P36: =R36*1.15 -> 0.2645 | Q36: 1 | R36: 0.23 | S36: 0.23 | T36: 0.0041047642 | U36: 0.0041047642 | V36: 0.0041047642 | W36: 0.0041047642 | X36: 0.0657583 | Y36: 0.0436711592742046;0.051181123470062;0.0613711445667025 | Z36: 0.0436711592742046;0.051181123470062;0.0613711445667025 | AA36: 63 | AB36: 849
A37: Unsec Std - 899 / 120 | B37: 0 | C37: prime | D37: PRIME | E37: 0.0165 | F37: 0.0115 | G37: standard | H37: 2e-05 | I37: 0.15 | J37: 0.9825 | K37: TRUE | L37: =T37*1.3 -> 0 | M37: 0 | N37: =V37*1.3 -> 0.0416 | O37: 0.0416 | P37: =R37*1.15 -> 0.138 | Q37: 1 | R37: 0.12 | S37: 0.12 | T37: 0 | U37: 0 | V37: 0.032 | W37: 0.032 | X37: 0.050711555 | Y37: 0 | Z37: 0 | AA37: 120 | AB37: 899
A38: Unsec Std - 899 / 132 | B38: 12 | C38: prime | D38: PRIME | E38: 0.0165 | F38: 0.0115 | G38: hybrid | H38: 2e-05 | I38: 0.15 | J38: 0.9825 | K38: TRUE | L38: =T38*1.3 -> 0.0060032177 | M38: 0.0060032177 | N38: =V38*1.3 -> 0.0060032177 | O38: 0.0060032177 | P38: =R38*1.15 -> 0.2645 | Q38: 1 | R38: 0.23 | S38: 0.23 | T38: 0.0046178598 | U38: 0.0046178598 | V38: 0.0046178598 | W38: 0.0046178598 | X38: 0.057211783 | Y38: 0.034087798153406;0.029131872311023;0.029131872311023;0.025455429050157;0.025455429050157;0.024935476432192;0.024935476432192;0.0330338174243784;0.0330338174243784;0.052503321664899;0.0723270250344311;0.115968664711763 | Z38: 0.034087798153406;0.029131872311023;0.029131872311023;0.025455429050157;0.025455429050157;0.024935476432192;0.024935476432192;0.0330338174243784;0.0330338174243784;0.052503321664899;0.0723270250344311;0.115968664711763 | AA38: 132 | AB38: 899
A39: Unsec Std - 899 / 180 | B39: 0 | C39: prime | D39: PRIME | E39: 0.0165 | F39: 0.0115 | G39: standard | H39: 2e-05 | I39: 0.15 | J39: 0.9825 | K39: TRUE | L39: =T39*1.3 -> 0 | M39: 0 | N39: =V39*1.3 -> 0.0416 | O39: 0.0416 | P39: =R39*1.15 -> 0.138 | Q39: 1 | R39: 0.12 | S39: 0.12 | T39: 0 | U39: 0 | V39: 0.032 | W39: 0.032 | X39: 0.049700226 | Y39: 0 | Z39: 0 | AA39: 180 | AB39: 899
A40: Unsec Std - 899 / 63 | B40: 3 | C40: prime | D40: PRIME | E40: 0.0165 | F40: 0.0115 | G40: hybrid | H40: 2e-05 | I40: 0.15 | J40: 1.005 | K40: TRUE | L40: =T40*1.3 -> 0.0053361935 | M40: 0.0053361935 | N40: =V40*1.3 -> 0.0053361935 | O40: 0.0053361935 | P40: =R40*1.15 -> 0.2645 | Q40: 1 | R40: 0.23 | S40: 0.23 | T40: 0.0041047642 | U40: 0.0041047642 | V40: 0.0041047642 | W40: 0.0041047642 | X40: 0.069972552 | Y40: 0.0436711592742046;0.051181123470062;0.0613711445667025 | Z40: 0.0436711592742046;0.051181123470062;0.0613711445667025 | AA40: 63 | AB40: 899
A41: Unsec Std - 949 - 120 | B41: 0 | C41: prime | D41: PRIME | E41: 0.0165 | F41: 0.0115 | G41: standard | H41: 2e-05 | I41: 0.15 | J41: 0.9825 | K41: TRUE | L41: =T41*1.3 -> 0 | M41: 0 | N41: =V41*1.3 -> 0.0364 | O41: 0.0364 | P41: =R41*1.15 -> 0.138 | Q41: 1 | R41: 0.12 | S41: 0.12 | T41: 0 | U41: 0 | V41: 0.028 | W41: 0.028 | X41: 0.075865399 | Y41: 0 | Z41: 0 | AA41: 120 | AB41: 949
A42: Unsec Std - 949 - 132 | B42: 12 | C42: prime | D42: PRIME | E42: 0.0165 | F42: 0.0115 | G42: hybrid | H42: 2e-05 | I42: 0.15 | J42: 0.9825 | K42: TRUE | L42: =T42*1.3 -> 0.00754 | M42: 0.00754 | N42: =V42*1.3 -> 0.0060032177 | O42: 0.0060032177 | P42: =R42*1.15 -> 0.2645 | Q42: 1 | R42: 0.23 | S42: 0.23 | T42: 0.0058 | U42: 0.0058 | V42: 0.0046178598 | W42: 0.0046178598 | X42: 0.059621221 | Y42: 0.034087798153406;0.029131872311023;0.029131872311023;0.025455429050157;0.025455429050157;0.024935476432192;0.024935476432192;0.0330338174243784;0.0330338174243784;0.052503321664899;0.0723270250344311;0.115968664711763 | Z42: 0.034087798153406;0.029131872311023;0.029131872311023;0.025455429050157;0.025455429050157;0.024935476432192;0.024935476432192;0.0330338174243784;0.0330338174243784;0.052503321664899;0.0723270250344311;0.115968664711763 | AA42: 132 | AB42: 949
A43: Unsec Std - 949 - 63 | B43: 3 | C43: prime | D43: PRIME | E43: 0.0165 | F43: 0.0115 | G43: hybrid | H43: 2e-05 | I43: 0.15 | J43: 1.005 | K43: TRUE | L43: =T43*1.3 -> 0.00676 | M43: 0.00676 | N43: =V43*1.3 -> 0.0053361935 | O43: 0.0053361935 | P43: =R43*1.15 -> 0.2645 | Q43: 1 | R43: 0.23 | S43: 0.23 | T43: 0.0052 | U43: 0.0052 | V43: 0.0041047642 | W43: 0.0041047642 | X43: 0.074040846 | Y43: 0.0436711592742046;0.051181123470062;0.0613711445667025 | Z43: 0.0436711592742046;0.051181123470062;0.0613711445667025 | AA43: 63 | AB43: 949
A44: Unsec Std - EPNI 36 Mo | B44: 36 | C44: prime | D44: PRIME | E44: 0.0165 | F44: 0.0115 | G44: epni | H44: 2e-05 | I44: 0.15 | J44: 0.92 | K44: TRUE | L44: =T44*1.3 -> 0 | M44: 0 | N44: =V44*1.3 -> 0.014380391 | O44: 0.014380391 | P44: =R44*1.15 -> 0.2461 | Q44: 1 | R44: 0.214 | S44: 0.214 | T44: 0 | U44: 0 | V44: 0.011061839 | W44: 0.011061839 | X44: 0.059255891 | Y44: 0 | Z44: 0 | AA44: 36 | AB44: 0
A45: Unsec Std - EPNI 60 Mo | B45: 60 | C45: prime | D45: PRIME | E45: 0.0165 | F45: 0.0115 | G45: epni | H45: 2e-05 | I45: 0.15 | J45: 0.885 | K45: TRUE | L45: =T45*1.3 -> 0 | M45: 0 | N45: =V45*1.3 -> 0.013407174 | O45: 0.013407174 | P45: =R45*1.15 -> 0.15985 | Q45: 1 | R45: 0.139 | S45: 0.139 | T45: 0 | U45: 0 | V45: 0.010313211 | W45: 0.010313211 | X45: 0.05356764 | Y45: 0 | Z45: 0 | AA45: 60 | AB45: 0
A46: 6 Mth BD WPDI | B46: 6 | C46: sfy | D46: BD | E46: 0.02 | F46: 0.0125 | G46: wpdi_bd | H46: 2e-05 | I46: 0.15 | J46: 0.9135 | K46: TRUE | L46: =T46*1.3 -> 0.12532 | M46: 0.12532 | N46: =V46*1.3 -> 0.12532 | O46: 0.12532 | P46: =R46*1.15 -> 0.269675 | Q46: 1 | R46: 0.2345 | S46: 0.2345 | T46: 0.0964 | U46: 0.0964 | V46: 0.0964 | W46: 0.0964 | X46: 0.1578011 | Y46: 0.014038095;0.02807619;0.042114286;0.056152381;0.070190476;0.084228571 | Z46: 0.014038095;0.02807619;0.042114286;0.056152381;0.070190476;0.084228571 | AA46: 61 | AB46: 1599
A47: 6 Mth BD WPDI 12S | B47: 12 | C47: sfy | D47: BD | E47: 0.02 | F47: 0.0125 | G47: wpdi_bd | H47: 2e-05 | I47: 0.15 | J47: 0.9135 | K47: TRUE | L47: =T47*1.3 -> 0.12532 | M47: 0.12532 | N47: =V47*1.3 -> 0.12532 | O47: 0.12532 | P47: =R47*1.15 -> 0.27485 | Q47: 1 | R47: 0.239 | S47: 0.239 | T47: 0.0964 | U47: 0.0964 | V47: 0.0964 | W47: 0.0964 | X47: 0.12729977 | Y47: 0.006064103;0.012128205;0.018192308;0.02425641;0.030320513;0.036384615;0.042448718;0.048512821;0.054576923;0.060641026;0.066705128;0.072769231 | Z47: 0.006064103;0.012128205;0.018192308;0.02425641;0.030320513;0.036384615;0.042448718;0.048512821;0.054576923;0.060641026;0.066705128;0.072769231 | AA47: 63 | AB47: 1599
A48: Unsec Std - 1049 - 132 | B48: 12 | C48: sfy | D48: SFY | E48: 0.02 | F48: 0.0125 | G48: hybrid | H48: 2e-05 | I48: 0.15 | J48: 0.975 | K48: TRUE | L48: =T48*1.3 -> 0.027451008 | M48: 0.027451008 | N48: =V48*1.3 -> 0.027451008 | O48: 0.027451008 | P48: =R48*1.15 -> 0.2645 | Q48: 1 | R48: 0.23 | S48: 0.23 | T48: 0.02111616 | U48: 0.02111616 | V48: 0.02111616 | W48: 0.02111616 | X48: 0.054664883 | Y48: 0.034087798153406;0.029131872311023;0.029131872311023;0.025455429050157;0.025455429050157;0.024935476432192;0.024935476432192;0.0330338174243784;0.0330338174243784;0.052503321664899;0.0723270250344311;0.115968664711763 | Z48: 0.034087798153406;0.029131872311023;0.029131872311023;0.025455429050157;0.025455429050157;0.024935476432192;0.024935476432192;0.0330338174243784;0.0330338174243784;0.052503321664899;0.0723270250344311;0.115968664711763 | AA48: 132 | AB48: 1049
A49: Unsec Std - 1049 - 186 | B49: 6 | C49: sfy | D49: SFY | E49: 0.02 | F49: 0.0125 | G49: hybrid | H49: 2e-05 | I49: 0.15 | J49: 0.985 | K49: TRUE | L49: =T49*1.3 -> 0.023644452 | M49: 0.023644452 | N49: =V49*1.3 -> 0.023644452 | O49: 0.023644452 | P49: =R49*1.15 -> 0.2645 | Q49: 1 | R49: 0.23 | S49: 0.23 | T49: 0.01818804 | U49: 0.01818804 | V49: 0.01818804 | W49: 0.01818804 | X49: 0.073033018 | Y49: 0.0489849142849816;0.0428030164624041;0.0419287220074737;0.0555459909257746;0.0882837424238861;0.116654180496246 | Z49: 0.0489849142849816;0.0428030164624041;0.0419287220074737;0.0555459909257746;0.0882837424238861;0.116654180496246 | AA49: 186 | AB49: 1049
A50: Unsec Std - 1049 - 63 | B50: 3 | C50: sfy | D50: SFY | E50: 0.02 | F50: 0.0125 | G50: hybrid | H50: 2e-05 | I50: 0.15 | J50: 0.9975 | K50: TRUE | L50: =T50*1.3 -> 0.029738592 | M50: 0.029738592 | N50: =V50*1.3 -> 0.029738592 | O50: 0.029738592 | P50: =R50*1.15 -> 0.2645 | Q50: 1 | R50: 0.23 | S50: 0.23 | T50: 0.02287584 | U50: 0.02287584 | V50: 0.02287584 | W50: 0.02287584 | X50: 0.070468849 | Y50: 0.0436711592742046;0.051181123470062;0.0613711445667025 | Z50: 0.0436711592742046;0.051181123470062;0.0613711445667025 | AA50: 63 | AB50: 1049
A51: Unsec Std - 1099 - 120 | B51: 0 | C51: sfy | D51: SFY | E51: 0.02 | F51: 0.0125 | G51: standard | H51: 2e-05 | I51: 0.15 | J51: 0.8925 | K51: TRUE | L51: =T51*1.3 -> 0 | M51: 0 | N51: =V51*1.3 -> 0.12532 | O51: 0.12532 | P51: =R51*1.15 -> 0.18745 | Q51: 1 | R51: 0.163 | S51: 0.163 | T51: 0 | U51: 0 | V51: 0.0964 | W51: 0.0964 | X51: 0.067758858 | Y51: 0 | Z51: 0 | AA51: 120 | AB51: 1099
A52: Unsec Std - 1099 / 132 | B52: 12 | C52: sfy | D52: SFY | E52: 0.02 | F52: 0.0125 | G52: hybrid | H52: 2e-05 | I52: 0.15 | J52: 0.975 | K52: TRUE | L52: =T52*1.3 -> 0.027451008 | M52: 0.027451008 | N52: =V52*1.3 -> 0.027451008 | O52: 0.027451008 | P52: =R52*1.15 -> 0.2645 | Q52: 1 | R52: 0.23 | S52: 0.23 | T52: 0.02111616 | U52: 0.02111616 | V52: 0.02111616 | W52: 0.02111616 | X52: 0.057446902 | Y52: 0.034087798153406;0.029131872311023;0.029131872311023;0.025455429050157;0.025455429050157;0.024935476432192;0.024935476432192;0.0330338174243784;0.0330338174243784;0.052503321664899;0.0723270250344311;0.115968664711763 | Z52: 0.034087798153406;0.029131872311023;0.029131872311023;0.025455429050157;0.025455429050157;0.024935476432192;0.024935476432192;0.0330338174243784;0.0330338174243784;0.052503321664899;0.0723270250344311;0.115968664711763 | AA52: 132 | AB52: 1099
...

Sheet SFY-CPR
A1: Mth | B1: NINP3 | C1: NINP6 | D1: NINP12 | E1: NINP18 | F1: NINP24 | G1: NINP10 | H1: NINP14 | I1: NINP20 | J1: NINP4316 | K1: NINP4398 | L1: NINP4302 | M1: NINP4602 | N1: NINP4321 | O1: NINP4301 | P1: NINP4626 | Q1: NINP4332 | R1: NINP4312 | S1: NINP4632 | T1: NINP4612 | U1: NINP41232 | V1: NINP41207 | W1: NINP899/63 | X1: NINP1099/63 | Y1: NINP1199/63 | Z1: NINP1399/63 | AA1: NINP699/186 | AB1: NINP1099/186 | AC1: NINP1199/186 | AD1: NINP1399/186 | AE1: NINP899/132 | AF1: NINP1099/132 | AG1: NINP1199/132 | AH1: NINP1399/132 | AI1: NINP849-63 | AJ1: NINP1049-63 | AK1: NINP1149-63a | AL1: NINP1349-63 | AM1: NINP649-186 | AN1: NINP1049-186 | AO1: NINP1149-186a | AP1: NINP1349-186 | AQ1: NINP849-132 | AR1: NINP1049-132 | AS1: NINP1149-132a | AT1: NINP1349-132 | AU1: NINP949-63 | AV1: NINP1149-63 | AW1: NINP1249-63 | AX1: NINP1449-63 | AY1: NINP749-186 | AZ1: NINP1149-186 | BA1: NINP1249-186 | BB1: NINP1449-186 | BC1: NINP949-132 | BD1: NINP1149-132 | BE1: NINP1249-132 | BF1: NINP1449-132 | BG1: NINP649-132 | BH1: NINP1149-128 | BI1: NINP1349-128 | BJ1: NINP4396 | BK1: NINP4687 | BL1: NINP4213 | BM1: NINP4813 | BN1: NINP4013 | BO1: NINP4331 | BP1: NINP4337 | BQ1: NINP4342 | BR1: NINP4348 | BS1: NINP4355 | BT1: NINP4306 | BU1: NINP4313 | BV1: NINP4319 | BW1: NINP4325 | BX1: NINP4333 | BY1: NINP12n | BZ1: NINP18n | CA1: WP18n | CB1: WP24n | CC1: NINP849-183 | CD1: NINP1195-132 | CE1: WP6 | CF1: WP12 | CG1: WP18 | CH1: WP24 | CI1: WP10 | CJ1: WP14 | CK1: WP20
A2: 1 | B2: 0.33366367 | C2: 0.12881709 | D2: 0.06763335 | E2: 0.039703346 | F2: 0.03026823 | G2: 0.09 | H2: 0.045 | I2: 0.03 | J2: 0.050200338 | K2: 0.052132744 | L2: 0.028671159 | M2: 0.048984914 | N2: 0.045242224 | O2: 0.033671159 | P2: 0.067214363 | Q2: 0.047410486 | R2: 0.043671159 | S2: 0.067214363 | T2: 0.067214363 | U2: 0.047272958 | V2: 0.047272958 | W2: 0.043671159 | X2: 0.043671159 | Y2: 0.043671159 | Z2: 0.043671159 | AA2: 0.048984914 | AB2: 0.048984914 | AC2: 0.048984914 | AD2: 0.048984914 | AE2: 0.034087798 | AF2: 0.034087798 | AG2: 0.034087798 | AH2: 0.034087798 | AI2: 0.043671159 | AJ2: 0.043671159 | AK2: 0.043671159 | AL2: 0.043671159 | AM2: 0.048984914 | AN2: 0.048984914 | AO2: 0.048984914 | AP2: 0.048984914 | AQ2: 0.034087798 | AR2: 0.034087798 | AS2: 0.034087798 | AT2: 0.034087798 | AU2: 0.043671159 | AV2: 0.043671159 | AW2: 0.043671159 | AX2: 0.043671159 | AY2: 0.048984914 | AZ2: 0.048984914 | BA2: 0.048984914 | BB2: 0.048984914 | BC2: 0.034087798 | BD2: 0.034087798 | BE2: 0.034087798 | BF2: 0.034087798 | BG2: 0.034087798 | BH2: 0.051131697 | BI2: 0.051131697 | BJ2: 0.043671159 | BK2: 0.048984914 | BL2: 0.034087798 | BM2: 0.04 | BN2: 0.036 | BO2: 0.043671159 | BP2: 0.043671159 | BQ2: 0.043671159 | BR2: 0.043671159 | BS2: 0.043671159 | BT2: 0.043671159 | BU2: 0.043671159 | BV2: 0.043671159 | BW2: 0.043671159 | BX2: 0.043671159 | BY2: 0.064439053 | BZ2: 0.037828172 | CA2: 0.061498594 | CB2: 0.041451802 | CC2: 0.043671159 | CD2: 0.047272958 | CE2: 0.1895542 | CF2: 0.09742644 | CG2: 0.064594797 | CH2: 0.04353873 | CI2: 0.11 | CJ2: 0.057 | CK2: 0.055
A3: 2 | B3: 0.27123217 | C3: 0.10904923 | D3: 0.053375652 | E3: 0.036357159 | F3: 0.035600136 | G3: 0.06 | H3: 0.045 | I3: 0.03 | J3: 0.051770625 | K3: 0.053114819 | L3: 0.036181123 | M3: 0.042803016 | N3: 0.055332981 | O3: 0.041181123 | P3: 0.058731908 | Q3: 0.055563488 | R3: 0.051181123 | S3: 0.058731908 | T3: 0.058731908 | U3: 0.040400081 | V3: 0.040400081 | W3: 0.051181123 | X3: 0.051181123 | Y3: 0.051181123 | Z3: 0.051181123 | AA3: 0.042803016 | AB3: 0.042803016 | AC3: 0.042803016 | AD3: 0.042803016 | AE3: 0.029131872 | AF3: 0.029131872 | AG3: 0.029131872 | AH3: 0.029131872 | AI3: 0.051181123 | AJ3: 0.051181123 | AK3: 0.051181123 | AL3: 0.051181123 | AM3: 0.042803016 | AN3: 0.042803016 | AO3: 0.042803016 | AP3: 0.042803016 | AQ3: 0.029131872 | AR3: 0.029131872 | AS3: 0.029131872 | AT3: 0.029131872 | AU3: 0.051181123 | AV3: 0.051181123 | AW3: 0.051181123 | AX3: 0.051181123 | AY3: 0.042803016 | AZ3: 0.042803016 | BA3: 0.042803016 | BB3: 0.042803016 | BC3: 0.029131872 | BD3: 0.029131872 | BE3: 0.029131872 | BF3: 0.029131872 | BG3: 0.029131872 | BH3: 0.043697808 | BI3: 0.043697808 | BJ3: 0.051181123 | BK3: 0.042803016 | BL3: 0.029131872 | BM3: 0.04 | BN3: 0.036 | BO3: 0.051181123 | BP3: 0.051181123 | BQ3: 0.051181123 | BR3: 0.051181123 | BS3: 0.051181123 | BT3: 0.051181123 | BU3: 0.051181123 | BV3: 0.051181123 | BW3: 0.051181123 | BX3: 0.051181123 | BY3: 0.05085474 | BZ3: 0.034640024 | CA3: 0.043545474 | CB3: 0.028026264 | CC3: 0.051181123 | CD3: 0.040400081 | CE3: 0.12676458 | CF3: 0.067351181 | CG3: 0.045737811 | CH3: 0.029437272 | CI3: 0.07 | CJ3: 0.056 | CK3: 0.054
A4: 3 | B4: 0.37960416 | C4: 0.10644286 | D4: 0.053250045 | E4: 0.034709709 | F4: 0.02648995 | G4: 0.06 | H4: 0.045 | I4: 0.03 | J4: 0.067629037 | K4: 0.064352436 | L4: 0.046371145 | M4: 0.041928722 | N4: 0.069024794 | O4: 0.051371145 | P4: 0.05753225 | Q4: 0.066626026 | R4: 0.061371145 | S4: 0.05753225 | T4: 0.05753225 | U4: 0.040400081 | V4: 0.040400081 | W4: 0.061371145 | X4: 0.061371145 | Y4: 0.061371145 | Z4: 0.061371145 | AA4: 0.041928722 | AB4: 0.041928722 | AC4: 0.041928722 | AD4: 0.041928722 | AE4: 0.029131872 | AF4: 0.029131872 | AG4: 0.029131872 | AH4: 0.029131872 | AI4: 0.061371145 | AJ4: 0.061371145 | AK4: 0.061371145 | AL4: 0.061371145 | AM4: 0.041928722 | AN4: 0.041928722 | AO4: 0.041928722 | AP4: 0.041928722 | AQ4: 0.029131872 | AR4: 0.029131872 | AS4: 0.029131872 | AT4: 0.029131872 | AU4: 0.061371145 | AV4: 0.061371145 | AW4: 0.061371145 | AX4: 0.061371145 | AY4: 0.041928722 | AZ4: 0.041928722 | BA4: 0.041928722 | BB4: 0.041928722 | BC4: 0.029131872 | BD4: 0.029131872 | BE4: 0.029131872 | BF4: 0.029131872 | BG4: 0.029131872 | BH4: 0.043697808 | BI4: 0.043697808 | BJ4: 0.061371145 | BK4: 0.041928722 | BL4: 0.029131872 | BM4: 0.039 | BN4: 0.035 | BO4: 0.061371145 | BP4: 0.061371145 | BQ4: 0.061371145 | BR4: 0.061371145 | BS4: 0.061371145 | BT4: 0.061371145 | BU4: 0.061371145 | BV4: 0.061371145 | BW4: 0.061371145 | BX4: 0.061371145 | BY4: 0.050735066 | BZ4: 0.033070383 | CA4: 0.039774786 | CB4: 0.023879196 | CC4: 0.061371145 | CD4: 0.040400081 | CE4: 0.10935252 | CF4: 0.063170267 | CG4: 0.041777284 | CH4: 0.025081416 | CI4: 0.07 | CJ4: 0.056 | CK4: 0.048
A5: 4 | C5: 0.12017547 | D5: 0.054283117 | E5: 0.035482692 | F5: 0.027871366 | G5: 0.06 | H5: 0.045 | I5: 0.03 | M5: 0.055545991 | P5: 0.076217106 | S5: 0.076217106 | T5: 0.076217106 | U5: 0.035301589 | V5: 0.035301589 | AA5: 0.055545991 | AB5: 0.055545991 | AC5: 0.055545991 | AD5: 0.055545991 | AE5: 0.025455429 | AF5: 0.025455429 | AG5: 0.025455429 | AH5: 0.025455429 | AM5: 0.055545991 | AN5: 0.055545991 | AO5: 0.055545991 | AP5: 0.055545991 | AQ5: 0.025455429 | AR5: 0.025455429 | AS5: 0.025455429 | AT5: 0.025455429 | AY5: 0.055545991 | AZ5: 0.055545991 | BA5: 0.055545991 | BB5: 0.055545991 | BC5: 0.025455429 | BD5: 0.025455429 | BE5: 0.025455429 | BF5: 0.025455429 | BG5: 0.025455429 | BH5: 0.038183144 | BI5: 0.038183144 | BK5: 0.055545991 | BL5: 0.025455429 | BM5: 0.044 | BN5: 0.04 | BY5: 0.051719346 | BZ5: 0.033806858 | CA5: 0.038192667 | CB5: 0.024341818 | CD5: 0.035301589 | CE5: 0.12053361 | CF5: 0.060646889 | CG5: 0.040115511 | CH5: 0.025567329 | CI5: 0.07 | CJ5: 0.056 | CK5: 0.042
A6: 5 | C6: 0.1975722 | D6: 0.054772379 | E6: 0.037439796 | F6: 0.023758661 | G6: 0.06 | H6: 0.045 | I6: 0.03 | M6: 0.088283742 | P6: 0.12113802 | S6: 0.12113802 | T6: 0.12113802 | U6: 0.035301589 | V6: 0.035301589 | AA6: 0.088283742 | AB6: 0.088283742 | AC6: 0.088283742 | AD6: 0.088283742 | AE6: 0.025455429 | AF6: 0.025455429 | AG6: 0.025455429 | AH6: 0.025455429 | AM6: 0.088283742 | AN6: 0.088283742 | AO6: 0.088283742 | AP6: 0.088283742 | AQ6: 0.025455429 | AR6: 0.025455429 | AS6: 0.025455429 | AT6: 0.025455429 | AY6: 0.088283742 | AZ6: 0.088283742 | BA6: 0.088283742 | BB6: 0.088283742 | BC6: 0.025455429 | BD6: 0.025455429 | BE6: 0.025455429 | BF6: 0.025455429 | BG6: 0.025455429 | BH6: 0.038183144 | BI6: 0.038183144 | BK6: 0.088283742 | BL6: 0.025455429 | BM6: 0.05 | BN6: 0.04 | BY6: 0.0521855 | BZ6: 0.035671529 | CA6: 0.03689461 | CB6: 0.023940027 | CD6: 0.035301589 | CE6: 0.14001462 | CF6: 0.061915997 | CG6: 0.038752103 | CH6: 0.02514531 | CI6: 0.07 | CJ6: 0.056 | CK6: 0.032
A7: 6 | C7: 0.27934315 | D7: 0.054244757 | E7: 0.039737887 | F7: 0.025792207 | G7: 0.06 | H7: 0.045 | I7: 0.03 | M7: 0.11665418 | P7: 0.16006635 | S7: 0.16006635 | T7: 0.16006635 | U7: 0.034580519 | V7: 0.034580519 | AA7: 0.11665418 | AB7: 0.11665418 | AC7: 0.11665418 | AD7: 0.11665418 | AE7: 0.024935476 | AF7: 0.024935476 | AG7: 0.024935476 | AH7: 0.024935476 | AM7: 0.11665418 | AN7: 0.11665418 | AO7: 0.11665418 | AP7: 0.11665418 | AQ7: 0.024935476 | AR7: 0.024935476 | AS7: 0.024935476 | AT7: 0.024935476 | AY7: 0.11665418 | AZ7: 0.11665418 | BA7: 0.11665418 | BB7: 0.11665418 | BC7: 0.024935476 | BD7: 0.024935476 | BE7: 0.024935476 | BF7: 0.024935476 | BG7: 0.024935476 | BH7: 0.037403215 | BI7: 0.037403215 | BK7: 0.11665418 | BL7: 0.024935476 | BM7: 0.05 | BN7: 0.044 | BY7: 0.051682798 | BZ7: 0.037861082 | CA7: 0.036372926 | CB7: 0.024371182 | CD7: 0.034580519 | CE7: 0.18382748 | CF7: 0.060026785 | CG7: 0.038204154 | CH7: 0.025598171 | CI7: 0.07 | CJ7: 0.056 | CK7: 0.032
A8: 7 | D8: 0.056489571 | E8: 0.034907695 | F8: 0.021222931 | G8: 0.07 | H8: 0.045 | I8: 0.03 | U8: 0.034580519 | V8: 0.034580519 | AE8: 0.024935476 | AF8: 0.024935476 | AG8: 0.024935476 | AH8: 0.024935476 | AQ8: 0.024935476 | AR8: 0.024935476 | AS8: 0.024935476 | AT8: 0.024935476 | BC8: 0.024935476 | BD8: 0.024935476 | BE8: 0.024935476 | BF8: 0.024935476 | BG8: 0.024935476 | BH8: 0.037403215 | BI8: 0.037403215 | BL8: 0.024935476 | BM8: 0.06 | BN8: 0.044 | BY8: 0.05382159 | BZ8: 0.033259018 | CA8: 0.039268803 | CB8: 0.023149749 | CD8: 0.034580519 | CF8: 0.061692945 | CG8: 0.041245826 | CH8: 0.024315244 | CI8: 0.07 | CJ8: 0.056 | CK8: 0.032
A9: 8 | D9: 0.059411377 | E9: 0.035885356 | F9: 0.029632548 | G9: 0.08 | H9: 0.045 | I9: 0.03 | U9: 0.045811298 | V9: 0.045811298 | AE9: 0.033033817 | AF9: 0.033033817 | AG9: 0.033033817 | AH9: 0.033033817 | AQ9: 0.033033817 | AR9: 0.033033817 | AS9: 0.033033817 | AT9: 0.033033817 | BC9: 0.033033817 | BD9: 0.033033817 | BE9: 0.033033817 | BF9: 0.033033817 | BG9: 0.033033817 | BH9: 0.11596866 | BI9: 0.11596866 | BL9: 0.033033817 | BM9: 0.11 | BN9: 0.044 | BY9: 0.0566054 | BZ9: 0.034190504 | CA9: 0.038258358 | CB9: 0.022225741 | CD9: 0.045811298 | CF9: 0.063714385 | CG9: 0.04018451 | CH9: 0.023344716 | CI9: 0.08 | CJ9: 0.056 | CK9: 0.032
A10: 9 | D10: 0.066709985 | E10: 0.040163947 | F10: 0.029565746 | G10: 0.15 | H10: 0.045 | I10: 0.03 | U10: 0.045811298 | V10: 0.045811298 | AE10: 0.033033817 | AF10: 0.033033817 | AG10: 0.033033817 | AH10: 0.033033817 | AQ10: 0.033033817 | AR10: 0.033033817 | AS10: 0.033033817 | AT10: 0.033033817 | BC10: 0.033033817 | BD10: 0.033033817 | BE10: 0.033033817 | BF10: 0.033033817 | BG10: 0.033033817 | BL10: 0.033033817 | BN10: 0.06 | BY10: 0.063559298 | BZ10: 0.038267019 | CA10: 0.037784305 | CB10: 0.027951725 | CD10: 0.045811298 | CF10: 0.068177468 | CG10: 0.03968659 | CH10: 0.02935898 | CI10: 0.13 | CJ10: 0.057 | CK10: 0.032
A11: 10 | D11: 0.081659324 | E11: 0.036182784 | F11: 0.030828751 | G11: 0.23 | H11: 0.045 | I11: 0.03 | U11: 0.072811606 | V11: 0.072811606 | AE11: 0.052503322 | AF11: 0.052503322 | AG11: 0.052503322 | AH11: 0.052503322 | AQ11: 0.052503322 | AR11: 0.052503322 | AS11: 0.052503322 | AT11: 0.052503322 | BC11: 0.052503322 | BD11: 0.052503322 | BE11: 0.052503322 | BF11: 0.052503322 | BG11: 0.052503322 | BL11: 0.052503322 | BN11: 0.11 | BY11: 0.077802585 | BZ11: 0.034473885 | CA11: 0.039470383 | CB11: 0.024816806 | CD11: 0.072811606 | CF11: 0.085589652 | CG11: 0.041457555 | CH11: 0.02606623 | CI11: 0.16 | CJ11: 0.057 | CK11: 0.032
A12: 11 | D12: 0.14847544 | E12: 0.041062911 | F12: 0.038167371 | H12: 0.05 | I12: 0.03 | U12: 0.10030312 | V12: 0.10030312 | AE12: 0.072327025 | AF12: 0.072327025 | AG12: 0.072327025 | AH12: 0.072327025 | AQ12: 0.072327025 | AR12: 0.072327025 | AS12: 0.072327025 | AT12: 0.072327025 | BC12: 0.072327025 | BD12: 0.072327025 | BE12: 0.072327025 | BF12: 0.072327025 | BG12: 0.072327025 | BL12: 0.072327025 | BY12: 0.141463 | BZ12: 0.039123525 | CA12: 0.040068104 | CB12: 0.023766885 | CD12: 0.10030312 | CF12: 0.12657167 | CG12: 0.042085369 | CH12: 0.024963451 | CJ12: 0.057 | CK12: 0.032
A13: 12 | D13: 0.220095 | E13: 0.043798407 | F13: 0.030832404 | H13: 0.07 | I13: 0.03 | U13: 0.16082534 | V13: 0.16082534 | AE13: 0.11596866 | AF13: 0.11596866 | AG13: 0.11596866 | AH13: 0.11596866 | AQ13: 0.11596866 | AR13: 0.11596866 | AS13: 0.11596866 | AT13: 0.11596866 | BC13: 0.11596866 | BD13: 0.11596866 | BE13: 0.11596866 | BF13: 0.11596866 | BG13: 0.11596866 | BL13: 0.11596866 | BY13: 0.2097 | BZ13: 0.041729825 | CA13: 0.039653623 | CB13: 0.027194926 | CD13: 0.16082534 | CF13: 0.15501632 | CG13: 0.041650021 | CH13: 0.028564079 | CJ13: 0.058 | CK13: 0.032
A14: 13 | E14: 0.044275012 | F14: 0.030895519 | H14: 0.13 | I14: 0.03 | BZ14: 0.04218392 | CA14: 0.041587882 | CB14: 0.027466483 | CG14: 0.043681662 | CH14: 0.028849308 | CJ14: 0.098 | CK14: 0.032
A15: 14 | E15: 0.043314271 | F15: 0.028723293 | H15: 0.2 | I15: 0.03 | BZ15: 0.041268555 | CA15: 0.043048771 | CB15: 0.027301686 | CG15: 0.0452161 | CH15: 0.028676214 | CJ15: 0.125 | CK15: 0.032
A16: 15 | E16: 0.048749252 | F16: 0.032676297 | I16: 0.03 | BZ16: 0.046446844 | CA16: 0.049761672 | CB16: 0.029818524 | CG16: 0.052266969 | CH16: 0.031319764 | CK16: 0.032
A17: 16 | E17: 0.063602332 | F17: 0.021093038 | I17: 0.03 | BZ17: 0.060598418 | CA17: 0.061216191 | CB17: 0.027664467 | CG17: 0.064298175 | CH17: 0.02905726 | CK17: 0.032
A18: 17 | E18: 0.11510572 | F18: 0.027737116 | I18: 0.03 | BZ18: 0.10966932 | CA18: 0.099021288 | CB18: 0.027989778 | CG18: 0.10400661 | CH18: 0.029398949 | CK18: 0.032
A19: 18 | E19: 0.19432173 | F19: 0.037097547 | I19: 0.04 | BZ19: 0.18514399 | CA19: 0.12380584 | CB19: 0.029991663 | CG19: 0.13003896 | CH19: 0.031501621 | CK19: 0.067
A20: 19 | F20: 0.035807391 | I20: 0.14 | CB20: 0.036818572 | CH20: 0.038672236 | CK20: 0.098
A21: 20 | F21: 0.035803371 | I21: 0.19 | CB21: 0.04447365 | CH21: 0.046712716 | CK21: 0.125
A22: 21 | F22: 0.036391389 | CB22: 0.045817756 | CH22: 0.048124493
A23: 22 | F23: 0.063853619 | CB23: 0.066279674 | CH23: 0.069616584
A24: 23 | F24: 0.086512393 | CB24: 0.097478301 | CH24: 0.10238593
A25: 24 | F25: 0.096978726 | CB25: 0.12462941 | CH25: 0.13090399
B26: =_xlfn.CONCAT(B2,";",B3,";",B4,IF(ISBLANK(B5),"",";"),B5,IF(ISBLANK(B6),"",";"),B6,IF(ISBLANK(B7),"",";"),B7,IF(ISBLANK(B8),"",";"),B8,IF(ISBLANK(B9),"",";"),B9,IF(ISBLANK(B10),"",";"),B10,IF(ISBLANK(B11),"",";"),B11,IF(ISBLANK(B12),"",";"),B12,IF(ISBLANK(B13),"",";"),B13,IF(ISBLANK(B14),"",";"),B14,IF(ISBLANK(B15),"",";"),B15,IF(ISBLANK(B16),"",";"),B16,IF(ISBLANK(B17),"",";"),B17,IF(ISBLANK(B18),"",";"),B18,IF(ISBLANK(B19),"",";"),B19,IF(ISBLANK(B20),"",";"),B20,IF(ISBLANK(B21),"",";"),B21,IF(ISBLANK(B22),"",";"),B22,IF(ISBLANK(B23),"",";"),B23,IF(ISBLANK(B24),"",";"),B24,IF(ISBLANK(B25),"",";"),B25) -> 0.333663669422478;0.27123217065051;0.379604159927013 | C26: =_xlfn.CONCAT(C2,";",C3,";",C4,IF(ISBLANK(C5),"",";"),C5,IF(ISBLANK(C6),"",";"),C6,IF(ISBLANK(C7),"",";"),C7,IF(ISBLANK(C8),"",";"),C8,IF(ISBLANK(C9),"",";"),C9,IF(ISBLANK(C10),"",";"),C10,IF(ISBLANK(C11),"",";"),C11,IF(ISBLANK(C12),"",";"),C12,IF(ISBLANK(C13),"",";"),C13,IF(ISBLANK(C14),"",";"),C14,IF(ISBLANK(C15),"",";"),C15,IF(ISBLANK(C16),"",";"),C16,IF(ISBLANK(C17),"",";"),C17,IF(ISBLANK(C18),"",";"),C18,IF(ISBLANK(C19),"",";"),C19,IF(ISBLANK(C20),"",";"),C20,IF(ISBLANK(C21),"",";"),C21,IF(ISBLANK(C22),"",";"),C22,IF(ISBLANK(C23),"",";"),C23,IF(ISBLANK(C24),"",";"),C24,IF(ISBLANK(C25),"",";"),C25) -> 0.128817089271534;0.10904922611393;0.106442864313677;0.120175472098005;0.197572195306553;0.279343152896301 | D26: =_xlfn.CONCAT(D2,";",D3,";",D4,IF(ISBLANK(D5),"",";"),D5,IF(ISBLANK(D6),"",";"),D6,IF(ISBLANK(D7),"",";"),D7,IF(ISBLANK(D8),"",";"),D8,IF(ISBLANK(D9),"",";"),D9,IF(ISBLANK(D10),"",";"),D10,IF(ISBLANK(D11),"",";"),D11,IF(ISBLANK(D12),"",";"),D12,IF(ISBLANK(D13),"",";"),D13,IF(ISBLANK(D14),"",";"),D14,IF(ISBLANK(D15),"",";"),D15,IF(ISBLANK(D16),"",";"),D16,IF(ISBLANK(D17),"",";"),D17,IF(ISBLANK(D18),"",";"),D18,IF(ISBLANK(D19),"",";"),D19,IF(ISBLANK(D20),"",";"),D20,IF(ISBLANK(D21),"",";"),D21,IF(ISBLANK(D22),"",";"),D22,IF(ISBLANK(D23),"",";"),D23,IF(ISBLANK(D24),"",";"),D24,IF(ISBLANK(D25),"",";"),D25) -> 0.0676333498793084;0.0533756521010278;0.0532500454780047;0.0542831166094344;0.0547723788788143;0.0542447568131707;0.0564895709616642;0.0594113771367509;0.0667099854605115;0.0816593237270766;0.148475440070047;0.22009500288419 | E26: =_xlfn.CONCAT(E2,";",E3,";",E4,IF(ISBLANK(E5),"",";"),E5,IF(ISBLANK(E6),"",";"),E6,IF(ISBLANK(E7),"",";"),E7,IF(ISBLANK(E8),"",";"),E8,IF(ISBLANK(E9),"",";"),E9,IF(ISBLANK(E10),"",";"),E10,IF(ISBLANK(E11),"",";"),E11,IF(ISBLANK(E12),"",";"),E12,IF(ISBLANK(E13),"",";"),E13,IF(ISBLANK(E14),"",";"),E14,IF(ISBLANK(E15),"",";"),E15,IF(ISBLANK(E16),"",";"),E16,IF(ISBLANK(E17),"",";"),E17,IF(ISBLANK(E18),"",";"),E18,IF(ISBLANK(E19),"",";"),E19,IF(ISBLANK(E20),"",";"),E20,IF(ISBLANK(E21),"",";"),E21,IF(ISBLANK(E22),"",";"),E22,IF(ISBLANK(E23),"",";"),E23,IF(ISBLANK(E24),"",";"),E24,IF(ISBLANK(E25),"",";"),E25) -> 0.0397033461852658;0.0363571588299138;0.0347097092841171;0.0354826917146094;0.0374397958165012;0.039737887495065;0.0349076948107677;0.0358853559269975;0.0401639469945674;0.0361827842477967;0.0410629108672573;0.0437984067038958;0.0442750123745728;0.043314271123343;0.048749252320648;0.0636023317033571;0.115105715126378;0.194321728474946 | F26: =_xlfn.CONCAT(F2,";",F3,";",F4,IF(ISBLANK(F5),"",";"),F5,IF(ISBLANK(F6),"",";"),F6,IF(ISBLANK(F7),"",";"),F7,IF(ISBLANK(F8),"",";"),F8,IF(ISBLANK(F9),"",";"),F9,IF(ISBLANK(F10),"",";"),F10,IF(ISBLANK(F11),"",";"),F11,IF(ISBLANK(F12),"",";"),F12,IF(ISBLANK(F13),"",";"),F13,IF(ISBLANK(F14),"",";"),F14,IF(ISBLANK(F15),"",";"),F15,IF(ISBLANK(F16),"",";"),F16,IF(ISBLANK(F17),"",";"),F17,IF(ISBLANK(F18),"",";"),F18,IF(ISBLANK(F19),"",";"),F19,IF(ISBLANK(F20),"",";"),F20,IF(ISBLANK(F21),"",";"),F21,IF(ISBLANK(F22),"",";"),F22,IF(ISBLANK(F23),"",";"),F23,IF(ISBLANK(F24),"",";"),F24,IF(ISBLANK(F25),"",";"),F25) -> 0.0302682303390938;0.0356001359822339;0.0264899498130113;0.0278713659278495;0.0237586612170386;0.0257922068481641;0.0212229312672512;0.0296325482161332;0.0295657455342041;0.0308287508657281;0.0381673706394066;0.0308324037932695;0.0308955187188472;0.028723292961373;0.032676297334632;0.0210930382447866;0.0277371162310062;0.0370975473999753;0.035807390962314;0.035803371307891;0.0363913891800091;0.0638536190282034;0.0865123925721557;0.0969787256154225 | G26: =_xlfn.CONCAT(G2,";",G3,";",G4,IF(ISBLANK(G5),"",";"),G5,IF(ISBLANK(G6),"",";"),G6,IF(ISBLANK(G7),"",";"),G7,IF(ISBLANK(G8),"",";"),G8,IF(ISBLANK(G9),"",";"),G9,IF(ISBLANK(G10),"",";"),G10,IF(ISBLANK(G11),"",";"),G11,IF(ISBLANK(G12),"",";"),G12,IF(ISBLANK(G13),"",";"),G13,IF(ISBLANK(G14),"",";"),G14,IF(ISBLANK(G15),"",";"),G15,IF(ISBLANK(G16),"",";"),G16,IF(ISBLANK(G17),"",";"),G17,IF(ISBLANK(G18),"",";"),G18,IF(ISBLANK(G19),"",";"),G19,IF(ISBLANK(G20),"",";"),G20,IF(ISBLANK(G21),"",";"),G21,IF(ISBLANK(G22),"",";"),G22,IF(ISBLANK(G23),"",";"),G23,IF(ISBLANK(G24),"",";"),G24,IF(ISBLANK(G25),"",";"),G25) -> 0.09;0.06;0.06;0.06;0.06;0.06;0.07;0.08;0.15;0.23 | H26: =_xlfn.CONCAT(H2,";",H3,";",H4,IF(ISBLANK(H5),"",";"),H5,IF(ISBLANK(H6),"",";"),H6,IF(ISBLANK(H7),"",";"),H7,IF(ISBLANK(H8),"",";"),H8,IF(ISBLANK(H9),"",";"),H9,IF(ISBLANK(H10),"",";"),H10,IF(ISBLANK(H11),"",";"),H11,IF(ISBLANK(H12),"",";"),H12,IF(ISBLANK(H13),"",";"),H13,IF(ISBLANK(H14),"",";"),H14,IF(ISBLANK(H15),"",";"),H15,IF(ISBLANK(H16),"",";"),H16,IF(ISBLANK(H17),"",";"),H17,IF(ISBLANK(H18),"",";"),H18,IF(ISBLANK(H19),"",";"),H19,IF(ISBLANK(H20),"",";"),H20,IF(ISBLANK(H21),"",";"),H21,IF(ISBLANK(H22),"",";"),H22,IF(ISBLANK(H23),"",";"),H23,IF(ISBLANK(H24),"",";"),H24,IF(ISBLANK(H25),"",";"),H25) -> 0.045;0.045;0.045;0.045;0.045;0.045;0.045;0.045;0.045;0.045;0.05;0.07;0.13;0.2 | I26: =_xlfn.CONCAT(I2,";",I3,";",I4,IF(ISBLANK(I5),"",";"),I5,IF(ISBLANK(I6),"",";"),I6,IF(ISBLANK(I7),"",";"),I7,IF(ISBLANK(I8),"",";"),I8,IF(ISBLANK(I9),"",";"),I9,IF(ISBLANK(I10),"",";"),I10,IF(ISBLANK(I11),"",";"),I11,IF(ISBLANK(I12),"",";"),I12,IF(ISBLANK(I13),"",";"),I13,IF(ISBLANK(I14),"",";"),I14,IF(ISBLANK(I15),"",";"),I15,IF(ISBLANK(I16),"",";"),I16,IF(ISBLANK(I17),"",";"),I17,IF(ISBLANK(I18),"",";"),I18,IF(ISBLANK(I19),"",";"),I19,IF(ISBLANK(I20),"",";"),I20,IF(ISBLANK(I21),"",";"),I21,IF(ISBLANK(I22),"",";"),I22,IF(ISBLANK(I23),"",";"),I23,IF(ISBLANK(I24),"",";"),I24,IF(ISBLANK(I25),"",";"),I25) -> 0.03;0.03;0.03;0.03;0.03;0.03;0.03;0.03;0.03;0.03;0.03;0.03;0.03;0.03;0.03;0.03;0.03;0.04;0.14;0.19 | ... CK26: =_xlfn.CONCAT(CK2,";",CK3,";",CK4,IF(ISBLANK(CK5),"",";"),CK5,IF(ISBLANK(CK6),"",";"),CK6,IF(ISBLANK(CK7),"",";"),CK7,IF(ISBLANK(CK8),"",";"),CK8,IF(ISBLANK(CK9),"",";"),CK9,IF(ISBLANK(CK10),"",";"),CK10,IF(ISBLANK(CK11),"",";"),CK11,IF(ISBLANK(CK12),"",";"),CK12,IF(ISBLANK(CK13),"",";"),CK13,IF(ISBLANK(CK14),"",";"),CK14,IF(ISBLANK(CK15),"",";"),CK15,IF(ISBLANK(CK16),"",";"),CK16,IF(ISBLANK(CK17),"",";"),CK17,IF(ISBLANK(CK18),"",";"),CK18,IF(ISBLANK(CK19),"",";"),CK19,IF(ISBLANK(CK20),"",";"),CK20,IF(ISBLANK(CK21),"",";"),CK21,IF(ISBLANK(CK22),"",";"),CK22,IF(ISBLANK(CK23),"",";"),CK23,IF(ISBLANK(CK24),"",";"),CK24,IF(ISBLANK(CK25),"",";"),CK25) -> 0.055;0.054;0.048;0.042;0.032;0.032;0.032;0.032;0.032;0.032;0.032;0.032;0.032;0.032;0.032;0.032;0.032;0.067;0.098;0.125

Sheet SFC-Models-SFY
A1: Loan Product Variables | C1: Term of Loan in Mths (total) | D1: Avg Loan Size $'s | E1: Loan Interest Rate | F1: CDR - Promotion Period Only | G1: Constant Prepay Rate | H1: Servicing Fees | I1: Late Fees% UPB/Mth | J1: Default Recovery % | K1: Promotional Period Term | L1: Promo Period Prepayment | M1: SFC Selling Price | N1: SFC Loan Margin | O1: SFC Purchase Price | P1: Merchant Discount | Q1: CDR No Promo or Post Promo | R1: Single Pool Net Loan Yield
A2: NINP899/63 | B2: Unsec Std - 899 / 63 | C2: 63 | D2: 9084.7488 | E2: 0.0899 | F2: 0.0096455382 | G2: 0.23 | H2: 0 | I2: 2e-05 | J2: 0.15 | K2: 3 | L2: 0.15622343 | M2: 0.9975 | N2: 0.0125 | O2: 0.985 | P2: 0.015 | Q2: 0.0096455382 | R2: 0.069668314 | S2: =HLOOKUP(A2,'SFY-CPR'!$B$1:$CK$26,26,FALSE) -> 0.0436711592742046;0.051181123470062;0.0613711445667025
A3: NINP1099/63 | B3: Unsec Std - 1099 / 63 | C3: 63 | D3: 9084.7488 | E3: 0.1099 | F3: 0.02287584 | G3: 0.23 | H3: 0 | I3: 2e-05 | J3: 0.15 | K3: 3 | L3: 0.15622343 | M3: 0.9975 | N3: 0.0125 | O3: 0.985 | P3: 0.015 | Q3: 0.02287584 | R3: 0.074645872 | S3: =HLOOKUP(A3,'SFY-CPR'!$B$1:$CK$26,26,FALSE) -> 0.0436711592742046;0.051181123470062;0.0613711445667025
A4: NINP1199/63 | B4: Unsec Std - 1199 / 63 | C4: 63 | D4: 9084.7488 | E4: 0.1199 | F4: 0.020982 | G4: 0.23 | H4: 0 | I4: 2e-05 | J4: 0.15 | K4: 3 | L4: 0.15622343 | M4: 0.9975 | N4: 0.0125 | O4: 0.985 | P4: 0.015 | Q4: 0.020982 | R4: 0.084693796 | S4: =HLOOKUP(A4,'SFY-CPR'!$B$1:$CK$26,26,FALSE) -> 0.0436711592742046;0.051181123470062;0.0613711445667025
A5: NINP1399/63 | B5: Unsec Std - 1399 / 63 | C5: 63 | D5: 9084.7488 | E5: 0.1399 | F5: 0.04434144 | G5: 0.23 | H5: 0 | I5: 2e-05 | J5: 0.15 | K5: 3 | L5: 0.15622343 | M5: 0.9975 | N5: 0.0125 | O5: 0.985 | P5: 0.015 | Q5: 0.04434144 | R5: 0.080055138 | S5: =HLOOKUP(A5,'SFY-CPR'!$B$1:$CK$26,26,FALSE) -> 0.0436711592742046;0.051181123470062;0.0613711445667025
A6: NINP699/186 | B6: Unsec Std - 699 / 186 | C6: 186 | D6: 9084.7488 | E6: 0.0699 | F6: 0.00942552 | G6: 0.23 | H6: 0 | I6: 2e-05 | J6: 0.15 | K6: 6 | L6: 0.39420057 | M6: 0.985 | N6: 0.0125 | O6: 0.9725 | P6: 0.0275 | Q6: 0.00942552 | R6: 0.054046359 | S6: =HLOOKUP(A6,'SFY-CPR'!$B$1:$CK$26,26,FALSE) -> 0.0489849142849816;0.0428030164624041;0.0419287220074737;0.0555459909257746;0.0882837424238861;0.116654180496246
A7: NINP1099/186 | B7: Unsec Std - 1099 / 186 | C7: 186 | D7: 9084.7488 | E7: 0.1099 | F7: 0.01818804 | G7: 0.23 | H7: 0 | I7: 2e-05 | J7: 0.15 | K7: 6 | L7: 0.39420057 | M7: 0.985 | N7: 0.0125 | O7: 0.9725 | P7: 0.0275 | Q7: 0.01818804 | R7: 0.076803138 | S7: =HLOOKUP(A7,'SFY-CPR'!$B$1:$CK$26,26,FALSE) -> 0.0489849142849816;0.0428030164624041;0.0419287220074737;0.0555459909257746;0.0882837424238861;0.116654180496246
A8: NINP1199/186 | B8: Unsec Std - 1199 / 186 | C8: 186 | D8: 9084.7488 | E8: 0.1199 | F8: 0.0171288 | G8: 0.23 | H8: 0 | I8: 2e-05 | J8: 0.15 | K8: 6 | L8: 0.39420057 | M8: 0.985 | N8: 0.0125 | O8: 0.9725 | P8: 0.0275 | Q8: 0.0171288 | R8: 0.0852633 | S8: =HLOOKUP(A8,'SFY-CPR'!$B$1:$CK$26,26,FALSE) -> 0.0489849142849816;0.0428030164624041;0.0419287220074737;0.0555459909257746;0.0882837424238861;0.116654180496246
A9: NINP1399/186 | B9: Unsec Std - 1399 / 186 | C9: 186 | D9: 9084.7488 | E9: 0.1399 | F9: 0.03702192 | G9: 0.23 | H9: 0 | I9: 2e-05 | J9: 0.15 | K9: 6 | L9: 0.39420057 | M9: 0.985 | N9: 0.0125 | O9: 0.9725 | P9: 0.0275 | Q9: 0.03702192 | R9: 0.081951748 | S9: =HLOOKUP(A9,'SFY-CPR'!$B$1:$CK$26,26,FALSE) -> 0.0489849142849816;0.0428030164624041;0.0419287220074737;0.0555459909257746;0.0882837424238861;0.116654180496246
A10: NINP899/132 | B10: Unsec Std - 899 / 132 | C10: 132 | D10: 9084.7488 | E10: 0.0899 | F10: 0.010758485 | G10: 0.23 | H10: 0 | I10: 2e-05 | J10: 0.15 | K10: 12 | L10: 0.5 | M10: 0.975 | N10: 0.0125 | O10: 0.9625 | P10: 0.0375 | Q10: 0.010758485 | R10: 0.055514016 | S10: =HLOOKUP(A10,'SFY-CPR'!$B$1:$CK$26,26,FALSE) -> 0.034087798153406;0.029131872311023;0.029131872311023;0.025455429050157;0.025455429050157;0.024935476432192;0.024935476432192;0.0330338174243784;0.0330338174243784;0.052503321664899;0.0723270250344311;0.115968664711763
A11: NINP1099/132 | B11: Unsec Std - 1099 / 132 | C11: 132 | D11: 9084.7488 | E11: 0.1099 | F11: 0.02111616 | G11: 0.23 | H11: 0 | I11: 2e-05 | J11: 0.15 | K11: 12 | L11: 0.5 | M11: 0.975 | N11: 0.0125 | O11: 0.9625 | P11: 0.0375 | Q11: 0.02111616 | R11: 0.057446902 | S11: =HLOOKUP(A11,'SFY-CPR'!$B$1:$CK$26,26,FALSE) -> 0.034087798153406;0.029131872311023;0.029131872311023;0.025455429050157;0.025455429050157;0.024935476432192;0.024935476432192;0.0330338174243784;0.0330338174243784;0.052503321664899;0.0723270250344311;0.115968664711763
A12: NINP1199/132 | B12: Unsec Std - 1199 / 132 | C12: 132 | D12: 9084.7488 | E12: 0.1199 | F12: 0.02067 | G12: 0.23 | H12: 0 | I12: 2e-05 | J12: 0.15 | K12: 12 | L12: 0.5 | M12: 0.975 | N12: 0.0125 | O12: 0.9625 | P12: 0.0375 | Q12: 0.02067 | R12: 0.063387707 | S12: =HLOOKUP(A12,'SFY-CPR'!$B$1:$CK$26,26,FALSE) -> 0.034087798153406;0.029131872311023;0.029131872311023;0.025455429050157;0.025455429050157;0.024935476432192;0.024935476432192;0.0330338174243784;0.0330338174243784;0.052503321664899;0.0723270250344311;0.115968664711763
A13: NINP1399/132 | B13: Unsec Std - 1399 / 132 | C13: 132 | D13: 9084.7488 | E13: 0.1399 | F13: 0.04221984 | G13: 0.23 | H13: 0 | I13: 2e-05 | J13: 0.15 | K13: 12 | L13: 0.5 | M13: 0.975 | N13: 0.0125 | O13: 0.9625 | P13: 0.0375 | Q13: 0.04221984 | R13: 0.05451089 | S13: =HLOOKUP(A13,'SFY-CPR'!$B$1:$CK$26,26,FALSE) -> 0.034087798153406;0.029131872311023;0.029131872311023;0.025455429050157;0.025455429050157;0.024935476432192;0.024935476432192;0.0330338174243784;0.0330338174243784;0.052503321664899;0.0723270250344311;0.115968664711763
A14: 899/120 | B14: Unsec Std - 899 / 120 | C14: 120 | D14: 10000 | E14: 0.0899 | G14: 0.12 | H14: 0.02 | I14: 2e-05 | J14: 0.15 | M14: 0.975 | N14: 0.0125 | O14: 0.9625 | P14: 0.0375 | Q14: 0.032 | R14: 0.049643393 | S14: =HLOOKUP(A14,'SFY-CPR'!$B$1:$CK$26,26,FALSE) -> #N/A
A15: 899/180 | B15: Unsec Std - 899 / 180 | C15: 180 | D15: 10000 | E15: 0.0899 | G15: 0.12 | H15: 0.02 | I15: 2e-05 | J15: 0.15 | M15: 0.975 | N15: 0.0125 | O15: 0.9625 | P15: 0.0375 | Q15: 0.032 | R15: 0.048187666 | S15: =HLOOKUP(A15,'SFY-CPR'!$B$1:$CK$26,26,FALSE) -> #N/A
A16: 399-60 | B16: Unsec Std - 399 - 60 | C16: 60 | D16: 10000 | E16: 0.0399 | G16: 0.1 | H16: 0.02 | I16: 2e-05 | J16: 0.15 | M16: 0.9225 | N16: 0.0125 | O16: 0.91 | P16: 0.09 | Q16: 0.032 | R16: 0.03029318 | S16: =HLOOKUP(A16,'SFY-CPR'!$B$1:$CK$26,26,FALSE) -> #N/A
A17: 399-84 | B17: Unsec Std - 399 - 84 | C17: 84 | D17: 10000 | E17: 0.0399 | G17: 0.1 | H17: 0.02 | I17: 2e-05 | J17: 0.15 | M17: 0.9125 | N17: 0.0125 | O17: 0.9 | P17: 0.1 | Q17: 0.032 | R17: 0.025515495 | S17: =HLOOKUP(A17,'SFY-CPR'!$B$1:$CK$26,26,FALSE) -> #N/A
A18: 1440-120 | B18: Unsec Std - 1440 - 120 | C18: 120 | D18: 10000 | E18: 0.144 | G18: 0.163 | H18: 0.02 | I18: 2e-05 | J18: 0.15 | M18: 0.9625 | N18: 0.0125 | O18: 0.95 | P18: 0.05 | Q18: 0.0964 | R18: 0.050693988 | S18: =HLOOKUP(A18,'SFY-CPR'!$B$1:$CK$26,26,FALSE) -> #N/A
A19: 6MBD | B19: 6 Mth BD WPDI | C19: 61 | D19: 5719 | E19: 0.2147 | F19: 0.0964 | G19: 0.2345 | H19: 0.02 | I19: 2e-05 | J19: 0.15 | K19: 6 | L19: 0.2948 | M19: 0.9135 | N19: 0.0125 | O19: 0.901 | P19: 0.099 | Q19: 0.0964 | R19: 0.1578011 | S19: =HLOOKUP(A19,'SFY-CPR'!$B$1:$CK$26,26,FALSE) -> #N/A
A20: 12MBD | B20: 6 Mth BD WPDI 12S | C20: 63 | D20: 6630 | E20: 0.2187 | F20: 0.0964 | G20: 0.239 | H20: 0.02 | I20: 2e-05 | J20: 0.15 | K20: 12 | L20: 0.473 | M20: 0.9135 | N20: 0.0125 | O20: 0.901 | P20: 0.099 | Q20: 0.0964 | R20: 0.12729977 | S20: =HLOOKUP(A20,'SFY-CPR'!$B$1:$CK$26,26,FALSE) -> #N/A
A21: 849-120 | B21: Unsec Std - 849 - 120 | C21: 120 | D21: 10000 | E21: 0.0849 | G21: 0.12 | H21: 0 | I21: 2e-05 | J21: 0.15 | M21: 0.975 | N21: 0.0125 | O21: 0.9625 | P21: 0.0375 | Q21: 0.032 | R21: 0.064864091 | S21: =HLOOKUP(A21,'SFY-CPR'!$B$1:$CK$26,26,FALSE) -> #N/A
A22: 849-180 | B22: Unsec Std - 849 - 180 | C22: 180 | D22: 10000 | E22: 0.0849 | G22: 0.12 | H22: 0 | I22: 2e-05 | J22: 0.15 | M22: 0.975 | N22: 0.0125 | O22: 0.9625 | P22: 0.0375 | Q22: 0.032 | R22: 0.063424106 | S22: =HLOOKUP(A22,'SFY-CPR'!$B$1:$CK$26,26,FALSE) -> #N/A
A23: 155PF | B23: Unsec Std - 1390 - 120 | C23: 120 | D23: 10000 | E23: 0.139 | G23: 0.163 | H23: 0 | I23: 2e-05 | J23: 0.15 | M23: 0.9625 | N23: 0.0125 | O23: 0.95 | P23: 0.05 | Q23: 0.0964 | R23: 0.065834672 | S23: =HLOOKUP(A23,'SFY-CPR'!$B$1:$CK$26,26,FALSE) -> #N/A
A24: NINP849-63 | B24: Unsec Std - 849 - 63 | C24: 63 | D24: 9084.7488 | E24: 0.0849 | F24: 0.0096455382 | G24: 0.23 | H24: 0 | I24: 2e-05 | J24: 0.15 | K24: 3 | L24: 0.15622343 | M24: 0.9975 | N24: 0.0125 | O24: 0.985 | P24: 0.015 | Q24: 0.0096455382 | R24: 0.065451837 | S24: =HLOOKUP(A24,'SFY-CPR'!$B$1:$CK$26,26,FALSE) -> 0.0436711592742046;0.051181123470062;0.0613711445667025
A25: NINP1049-63 | B25: Unsec Std - 1049 - 63 | C25: 63 | D25: 9084.7488 | E25: 0.1049 | F25: 0.02287584 | G25: 0.23 | H25: 0 | I25: 2e-05 | J25: 0.15 | K25: 3 | L25: 0.15622343 | M25: 0.9975 | N25: 0.0125 | O25: 0.985 | P25: 0.015 | Q25: 0.02287584 | R25: 0.070468849 | S25: =HLOOKUP(A25,'SFY-CPR'!$B$1:$CK$26,26,FALSE) -> 0.0436711592742046;0.051181123470062;0.0613711445667025
A26: NINP1349-63 | B26: Unsec Std - 1349 - 63 | C26: 63 | D26: 9084.7488 | E26: 0.1349 | F26: 0.04434144 | G26: 0.23 | H26: 0 | I26: 2e-05 | J26: 0.15 | K26: 3 | L26: 0.15622343 | M26: 0.9975 | N26: 0.0125 | O26: 0.985 | P26: 0.015 | Q26: 0.04434144 | R26: 0.075940043 | S26: =HLOOKUP(A26,'SFY-CPR'!$B$1:$CK$26,26,FALSE) -> 0.0436711592742046;0.051181123470062;0.0613711445667025
A27: NINP649-186 | B27: Unsec Std - 649 - 186 | C27: 186 | D27: 9084.7488 | E27: 0.0649 | F27: 0.00942552 | G27: 0.23 | H27: 0 | I27: 2e-05 | J27: 0.15 | K27: 6 | L27: 0.39420057 | M27: 0.985 | N27: 0.0125 | O27: 0.9725 | P27: 0.0275 | Q27: 0.00942552 | R27: 0.050167019 | S27: =HLOOKUP(A27,'SFY-CPR'!$B$1:$CK$26,26,FALSE) -> 0.0489849142849816;0.0428030164624041;0.0419287220074737;0.0555459909257746;0.0882837424238861;0.116654180496246
A28: NINP1049-186 | B28: Unsec Std - 1049 - 186 | C28: 186 | D28: 9084.7488 | E28: 0.1049 | F28: 0.01818804 | G28: 0.23 | H28: 0 | I28: 2e-05 | J28: 0.15 | K28: 6 | L28: 0.39420057 | M28: 0.985 | N28: 0.0125 | O28: 0.9725 | P28: 0.0275 | Q28: 0.01818804 | R28: 0.073033018 | S28: =HLOOKUP(A28,'SFY-CPR'!$B$1:$CK$26,26,FALSE) -> 0.0489849142849816;0.0428030164624041;0.0419287220074737;0.0555459909257746;0.0882837424238861;0.116654180496246
A29: NINP1149-186a | B29: #N/A | C29: 186 | D29: 9084.7488 | E29: 0.1149 | F29: 0.0171288 | G29: 0.23 | H29: 0 | I29: 2e-05 | J29: 0.15 | K29: 6 | L29: 0.39420057 | M29: 0.985 | N29: 0.0125 | O29: 0.9725 | P29: 0.0275 | Q29: 0.0171288 | R29: 0.081515636 | S29: =HLOOKUP(A29,'SFY-CPR'!$B$1:$CK$26,26,FALSE) -> 0.0489849142849816;0.0428030164624041;0.0419287220074737;0.0555459909257746;0.0882837424238861;0.116654180496246
A30: NINP1349-186 | B30: Unsec Std - 1349 - 186 | C30: 186 | D30: 9084.7488 | E30: 0.1349 | F30: 0.03702192 | G30: 0.23 | H30: 0 | I30: 2e-05 | J30: 0.15 | K30: 6 | L30: 0.39420057 | M30: 0.985 | N30: 0.0125 | O30: 0.9725 | P30: 0.0275 | Q30: 0.03702192 | R30: 0.078291412 | S30: =HLOOKUP(A30,'SFY-CPR'!$B$1:$CK$26,26,FALSE) -> 0.0489849142849816;0.0428030164624041;0.0419287220074737;0.0555459909257746;0.0882837424238861;0.116654180496246
A31: NINP849-132 | B31: Unsec Std - 849 - 132 | C31: 132 | D31: 9084.7488 | E31: 0.0849 | F31: 0.010758485 | G31: 0.23 | H31: 0 | I31: 2e-05 | J31: 0.15 | K31: 12 | L31: 0.5 | M31: 0.975 | N31: 0.0125 | O31: 0.9625 | P31: 0.0375 | Q31: 0.010758485 | R31: 0.052671865 | S31: =HLOOKUP(A31,'SFY-CPR'!$B$1:$CK$26,26,FALSE) -> 0.034087798153406;0.029131872311023;0.029131872311023;0.025455429050157;0.025455429050157;0.024935476432192;0.024935476432192;0.0330338174243784;0.0330338174243784;0.052503321664899;0.0723270250344311;0.115968664711763
A32: NINP1049-132 | B32: Unsec Std - 1049 - 132 | C32: 132 | D32: 9084.7488 | E32: 0.1049 | F32: 0.02111616 | G32: 0.23 | H32: 0 | I32: 2e-05 | J32: 0.15 | K32: 12 | L32: 0.5 | M32: 0.975 | N32: 0.0125 | O32: 0.9625 | P32: 0.0375 | Q32: 0.02111616 | R32: 0.054664883 | S32: =HLOOKUP(A32,'SFY-CPR'!$B$1:$CK$26,26,FALSE) -> 0.034087798153406;0.029131872311023;0.029131872311023;0.025455429050157;0.025455429050157;0.024935476432192;0.024935476432192;0.0330338174243784;0.0330338174243784;0.052503321664899;0.0723270250344311;0.115968664711763
A33: NINP1349-132 | B33: Unsec Std - 1349 - 132 | C33: 132 | D33: 9084.7488 | E33: 0.1349 | F33: 0.04221984 | G33: 0.23 | H33: 0 | I33: 2e-05 | J33: 0.15 | K33: 12 | L33: 0.5 | M33: 0.975 | N33: 0.0125 | O33: 0.9625 | P33: 0.0375 | Q33: 0.04221984 | R33: 0.051833322 | S33: =HLOOKUP(A33,'SFY-CPR'!$B$1:$CK$26,26,FALSE) -> 0.034087798153406;0.029131872311023;0.029131872311023;0.025455429050157;0.025455429050157;0.024935476432192;0.024935476432192;0.0330338174243784;0.0330338174243784;0.052503321664899;0.0723270250344311;0.115968664711763
A34: NINP949-63 | B34: Unsec Std - 949 - 63 | C34: 63 | D34: 9084.7488 | E34: 0.0949 | F34: 0.0052 | G34: 0.23 | H34: 0 | I34: 2e-05 | J34: 0.15 | K34: 3 | L34: 0.15622343 | M34: 0.9975 | N34: 0.0125 | O34: 0.985 | P34: 0.015 | Q34: 0.0096455382 | R34: 0.074458816 | S34: =HLOOKUP(A34,'SFY-CPR'!$B$1:$CK$26,26,FALSE) -> 0.0436711592742046;0.051181123470062;0.0613711445667025
A35: NINP1149-63 | B35: Unsec Std - 1149 - 63 | C35: 63 | D35: 9084.7488 | E35: 0.1149 | F35: 0.0156 | G35: 0.23 | H35: 0 | I35: 2e-05 | J35: 0.15 | K35: 3 | L35: 0.15622343 | M35: 0.9975 | N35: 0.0125 | O35: 0.985 | P35: 0.015 | Q35: 0.02287584 | R35: 0.079787006 | S35: =HLOOKUP(A35,'SFY-CPR'!$B$1:$CK$26,26,FALSE) -> 0.0436711592742046;0.051181123470062;0.0613711445667025
